Workbook

Sheet Curva de Calibração
K3: Y=0,1678x+0,0244 | O3: ABS | P3: ABS*VOL | Q3: C. Teorica | R3: C. Real
N4: 1 ppm | O4: 0.194 | P4: =0.194*50 -> 9.7 | Q4: 50 | R4: =(P4-0.0244)/0.1678 -> 57.661502
N5: 2 | O5: =0.398 -> 0.398 | P5: =0.398*50 -> 19.9 | Q5: 100 | R5: =(P5-0.0244)/0.1678 -> 118.44815
B6: Concetração | C6: Absorbância | N6: 20 | O6: 3.353 | P6: =3.353*50 -> 167.65 | Q6: 1000 | R6: =(P6-0.0244)/0.1678 -> 998.96067
B7: (ppm) | C7: (nm) | N7: 4 ppm | O7: 0.788 | P7: =0.788*50 -> 39.4 | Q7: 200 | R7: =(P7-0.0244)/0.1678 -> 234.65793
B8: 0.1 | C8: 0.011 | N8: desc. 1 | O8: 0.648 | P8: =0.648*50 -> 32.4 | Q8: 200 | R8: =(P8-0.0244)/0.1678 -> 192.9416
B9: 0.5 | C9: 0.086 | N9: desc. 2 | O9: 0.38 | P9: =0.38*50 -> 19 | Q9: 200 | R9: =(P9-0.0244)/0.1678 -> 113.08462
B10: 1 | C10: 0.194 | N10: SOL 4 | O10: 0.677 | P10: =O10*50 -> 33.85 | Q10: 200 | R10: =(P10-0.0244)/0.1678 -> 201.58284
B11: 2 | C11: 0.398 | N11: SOL 5 | O11: 0.811 | P11: =O11*50 -> 40.55 | Q11: 200 | R11: =(P11-0.0244)/0.1678 -> 241.51132
B12: 5 | C12: 0.848
B13: 10 | C13: 1.756
B14: 20 | C14: 3.353

Sheet pH PALMA
O3: ABS | P3: Concetração (ppm)
A4: Fibra da PalmaTratadas com Ácido | N4: 200 ppm | O4: 0.788 | P4: 234.66
A6: Valores de pH | C6: massa de semente (g) | E6: Absorbâncias (nm) | G6: Absorbâncias (nm) | I6: Concetração (ppm) | K6: Média (ppm) | L6: Desvio Padrão | M6: % Remoção | O6: Média % | P6: Desvio Padrão | Q6: QE (mg/g) | S6: Média | T6: Desvio Padrão
A7: Teorico | B7: Exp. | C7: m1 | D7: m2 | E7: abs1 | F7: abs2 | G7: abs 1 dil. | H7: abs 2 dil. | I7: [ ] 1 | J7: [ ] 2 | K7: concentração | Q7: 1 | R7: 2
A8: 2 | B8: 2.3 | C8: 0.1022 | D8: 0.1019 | E8: 0.49 | F8: 0.523 | G8: =E8*50 -> 24.5 | H8: =F8*50 -> 26.15 | I8: =(G8-0.0244)/0.1678 -> 145.86174 | J8: =(H8-0.0244)/0.1678 -> 155.69487 | K8: =(I8+J8)/2 -> 150.77831 | L8: =STDEV(I8:J8) -> 6.9530762 | M8: =(($P$4-I8)/$P$4)*100 -> 37.841243 | N8: =(($P$4-J8)/$P$4)*100 -> 33.650867 | O8: =(M8+N8)/2 -> 35.746055 | P8: =STDEV(M8:N8) -> 2.9630428 | Q8: =(($P$4-I8)/C8)*0.0244 -> 21.200367 | R8: =(($P$4-J8)/D8)*0.0244 -> 18.908234 | S8: =(Q8+R8)/2 -> 20.054301 | T8: =STDEV(Q8:R8) -> 1.6207829
A9: 4 | B9: 4.01 | C9: 0.1023 | D9: 0.1026 | E9: 0.317 | F9: 0.305 | G9: =E9*50 -> 15.85 | H9: =F9*50 -> 15.25 | I9: =(G9-0.0244)/0.1678 -> 94.312277 | J9: =(H9-0.0244)/0.1678 -> 90.736591 | K9: =(I9+J9)/2 -> 92.524434 | L9: =STDEV(I9:J9) -> 2.5283914 | M9: =(($P$4-I9)/$P$4)*100 -> 59.808968 | N9: =(($P$4-J9)/$P$4)*100 -> 61.33274 | O9: =(M9+N9)/2 -> 60.570854 | P9: =STDEV(M9:N9) -> 1.0774701 | Q9: =(($P$4-I9)/C9)*0.0244 -> 33.474921 | R9: =(($P$4-J9)/D9)*0.0244 -> 34.227399 | S9: =(Q9+R9)/2 -> 33.85116 | T9: =STDEV(Q9:R9) -> 0.53208232
A10: 6 | B10: 6.03 | C10: 0.1003 | D10: 0.1006 | E10: 0.285 | F10: 0.277 | G10: =E10*50 -> 14.25 | H10: =F10*50 -> 13.85 | I10: =(G10-0.0244)/0.1678 -> 84.777116 | J10: =(H10-0.0244)/0.1678 -> 82.393325 | K10: =(I10+J10)/2 -> 83.585221 | L10: =STDEV(I10:J10) -> 1.6855942 | M10: =(($P$4-I10)/$P$4)*100 -> 63.872362 | N10: =(($P$4-J10)/$P$4)*100 -> 64.88821 | O10: =(M10+N10)/2 -> 64.380286 | P10: =STDEV(M10:N10) -> 0.7183134 | Q10: =(($P$4-I10)/C10)*0.0244 -> 36.462038 | R10: =(($P$4-J10)/D10)*0.0244 -> 36.93148 | S10: =(Q10+R10)/2 -> 36.696759 | T10: =STDEV(Q10:R10) -> 0.33194566
A11: 8 | B11: 8.05 | C11: 0.1028 | D11: 0.1007 | E11: 0.125 | F11: 0.123 | G11: =E11*50 -> 6.25 | H11: =F11*50 -> 6.15 | I11: =(G11-0.0244)/0.1678 -> 37.101311 | J11: =(H11-0.0244)/0.1678 -> 36.505364 | K11: =(I11+J11)/2 -> 36.803337 | L11: =STDEV(I11:J11) -> 0.42139856 | M11: =(($P$4-I11)/$P$4)*100 -> 84.189333 | N11: =(($P$4-J11)/$P$4)*100 -> 84.443295 | O11: =(M11+N11)/2 -> 84.316314 | P11: =STDEV(M11:N11) -> 0.17957835 | Q11: =(($P$4-I11)/C11)*0.0244 -> 46.891362 | R11: =(($P$4-J11)/D11)*0.0244 -> 48.013636 | S11: =(Q11+R11)/2 -> 47.452499 | T11: =STDEV(Q11:R11) -> 0.79356748
A12: 10 | B12: 10.01 | C12: 0.1008 | D12: 0.1015 | E12: 0.084 | F12: 0.05 | G12: =E12*50 -> 4.2 | H12: =F12*50 -> 2.5 | I12: =(G12-0.0244)/0.1678 -> 24.884386 | J12: =(H12-0.0244)/0.1678 -> 14.753278 | K12: =(I12+J12)/2 -> 19.818832 | L12: =STDEV(I12:J12) -> 7.1637755 | M12: =(($P$4-I12)/$P$4)*100 -> 89.395557 | N12: =(($P$4-J12)/$P$4)*100 -> 93.712913 | O12: =(M12+N12)/2 -> 91.554235 | P12: =STDEV(M12:N12) -> 3.052832 | Q12: =(($P$4-I12)/C12)*0.0244 -> 50.779018 | R12: =(($P$4-J12)/D12)*0.0244 -> 52.864276 | S12: =(Q12+R12)/2 -> 51.821647 | T12: =STDEV(Q12:R12) -> 1.4745004
A20: Fibra da Palma In Natura
A21: Valores de pH | C21: massa de semente (g) | E21: Absorbâncias (nm) | G21: Absorbâncias (nm) | I21: Concetração (ppm) | K21: Média (ppm) | L21: Desvio Padrão | M21: % Remoção | O21: Média % | P21: Desvio Padrão | Q21: QE (mg/g) | S21: Média | T21: Desvio Padrão
A22: Teorico | B22: Exp. | C22: m1 | D22: m2 | E22: abs1 | F22: abs2 | G22: abs 1 dil. | H22: abs 2 dil. | I22: [ ] 1 | J22: [ ] 2 | K22: concentração | Q22: 1 | R22: 2
A23: 2 | B23: 2.16 | C23: 0.1015 | D23: 0.1019 | E23: 0.655 | F23: 0.652 | G23: =E23*50 -> 32.75 | H23: =F23*50 -> 32.6 | I23: =(G23-0.0244)/0.1678 -> 195.02741 | J23: =(H23-0.0244)/0.1678 -> 194.13349 | K23: =(I23+J23)/2 -> 194.58045 | L23: =STDEV(I23:J23) -> 0.63209784 | M23: =(($P$4-I23)/$P$4)*100 -> 16.889366 | N23: =(($P$4-J23)/$P$4)*100 -> 17.270309 | O23: =(M23+N23)/2 -> 17.079838 | P23: =STDEV(M23:N23) -> 0.26936753 | Q23: =(($P$4-I23)/C23)*0.001 -> 0.39046883 | R23: =(($P$4-J23)/D23)*0.001 -> 0.39770861 | S23: =(Q23+R23)/2 -> 0.39408872 | T23: =STDEV(Q23:R23) -> 0.0051192991
A24: 4 | B24: 4.24 | C24: 0.1013 | D24: 0.1003 | E24: 0.36 | F24: 0.391 | G24: =E24*50 -> 18 | H24: =F24*50 -> 19.55 | I24: =(G24-0.0244)/0.1678 -> 107.12515 | J24: =(H24-0.0244)/0.1678 -> 116.36234 | K24: =(I24+J24)/2 -> 111.74374 | L24: =STDEV(I24:J24) -> 6.5316777 | M24: =(($P$4-I24)/$P$4)*100 -> 54.348782 | N24: =(($P$4-J24)/$P$4)*100 -> 50.412368 | O24: =(M24+N24)/2 -> 52.380575 | P24: =STDEV(M24:N24) -> 2.7834644 | Q24: =(($P$4-I24)/C24)*0.001 -> 1.2589817 | R24: =(($P$4-J24)/D24)*0.001 -> 1.1794383 | S24: =(Q24+R24)/2 -> 1.21921 | T24: =STDEV(Q24:R24) -> 0.056245694
A25: 6 | B25: 6.03 | C25: 0.1007 | D25: 0.1014 | E25: 0.315 | F25: 0.274 | G25: =E25*50 -> 15.75 | H25: =F25*50 -> 13.7 | I25: =(G25-0.0244)/0.1678 -> 93.716329 | J25: =(H25-0.0244)/0.1678 -> 81.499404 | K25: =(I25+J25)/2 -> 87.607867 | L25: =STDEV(I25:J25) -> 8.6386704 | M25: =(($P$4-I25)/$P$4)*100 -> 60.06293 | N25: =(($P$4-J25)/$P$4)*100 -> 65.269154 | O25: =(M25+N25)/2 -> 62.666042 | P25: =STDEV(M25:N25) -> 3.6813562 | Q25: =(($P$4-I25)/C25)*0.001 -> 1.3996392 | R25: =(($P$4-J25)/D25)*0.001 -> 1.5104595 | S25: =(Q25+R25)/2 -> 1.4550494 | T25: =STDEV(Q25:R25) -> 0.078361779
A26: 8 | B26: 8.01 | C26: 0.1009 | D26: 0.1 | E26: 0.148 | F26: 0.098 | G26: =E26*50 -> 7.4 | H26: =F26*50 -> 4.9 | I26: =(G26-0.0244)/0.1678 -> 43.954708 | J26: =(H26-0.0244)/0.1678 -> 29.056019 | K26: =(I26+J26)/2 -> 36.505364 | L26: =STDEV(I26:J26) -> 10.534964 | M26: =(($P$4-I26)/$P$4)*100 -> 81.268768 | N26: =(($P$4-J26)/$P$4)*100 -> 87.617822 | O26: =(M26+N26)/2 -> 84.443295 | P26: =STDEV(M26:N26) -> 4.4894588 | Q26: =(($P$4-I26)/C26)*0.001 -> 1.8900425 | R26: =(($P$4-J26)/D26)*0.001 -> 2.0560398 | S26: =(Q26+R26)/2 -> 1.9730412 | T26: =STDEV(Q26:R26) -> 0.1173778
A27: 10 | B27: 10.15 | C27: 0.1008 | D27: 0.1016 | E27: 0.058 | F27: 0.059 | G27: =E27*50 -> 2.9 | H27: =F27*50 -> 2.95 | I27: =(G27-0.0244)/0.1678 -> 17.137068 | J27: =(H27-0.0244)/0.1678 -> 17.435042 | K27: =(I27+J27)/2 -> 17.286055 | L27: =STDEV(I27:J27) -> 0.21069928 | M27: =(($P$4-I27)/$P$4)*100 -> 92.697065 | N27: =(($P$4-J27)/$P$4)*100 -> 92.570084 | O27: =(M27+N27)/2 -> 92.633574 | P27: =STDEV(M27:N27) -> 0.089789176 | Q27: =(($P$4-I27)/C27)*0.001 -> 2.1579656 | R27: =(($P$4-J27)/D27)*0.001 -> 2.1380409 | S27: =(Q27+R27)/2 -> 2.1480033 | T27: =STDEV(Q27:R27) -> 0.014088868
A32: Fibra da Palma tratada com Base
A33: Valores de pH | C33: massa de semente (g) | E33: Absorbâncias (nm) | G33: Absorbâncias (nm) | I33: Concetração (ppm) | K33: Média (ppm) | L33: Desvio Padrão | M33: % Remoção | O33: Média % | P33: Desvio Padrão | Q33: QE (mg/g) | S33: Média | T33: Desvio Padrão
A34: Teorico | B34: Exp. | C34: m1 | D34: m2 | E34: abs1 | F34: abs2 | G34: abs 1 dil. | H34: abs 2 dil. | I34: [ ] 1 | J34: [ ] 2 | K34: concentração | Q34: 1 | R34: 2
A35: 2 | B35: 2.16 | C35: 0.1008 | D35: 0.1003 | E35: 0.486 | F35: 0.453 | G35: =E35*50 -> 24.3 | H35: =F35*50 -> 22.65 | I35: =(G35-0.0244)/0.1678 -> 144.66985 | J35: =(H35-0.0244)/0.1678 -> 134.83671 | K35: =(I35+J35)/2 -> 139.75328 | L35: =STDEV(I35:J35) -> 6.9530762 | M35: =(($P$4-I35)/$P$4)*100 -> 38.349167 | N35: =(($P$4-J35)/$P$4)*100 -> 42.539542 | O35: =(M35+N35)/2 -> 40.444355 | P35: =STDEV(M35:N35) -> 2.9630428 | Q35: =(($P$4-I35)/C35)*0.001 -> 0.89275947 | R35: =(($P$4-J35)/D35)*0.001 -> 0.99524715 | S35: =(Q35+R35)/2 -> 0.94400331 | T35: =STDEV(Q35:R35) -> 0.072469734
A36: 4 | B36: 4.24 | C36: 0.1007 | D36: 0.1021 | E36: 0.03 | F36: 0.026 | G36: =E36*50 -> 1.5 | H36: =F36*50 -> 1.3 | I36: =(G36-0.0244)/0.1678 -> 8.7938021 | J36: =(H36-0.0244)/0.1678 -> 7.601907 | K36: =(I36+J36)/2 -> 8.1978546 | L36: =STDEV(I36:J36) -> 0.84279712 | M36: =(($P$4-I36)/$P$4)*100 -> 96.252535 | N36: =(($P$4-J36)/$P$4)*100 -> 96.760459 | O36: =(M36+N36)/2 -> 96.506497 | P36: =STDEV(M36:N36) -> 0.3591567 | Q36: =(($P$4-I36)/C36)*0.001 -> 2.2429613 | R36: =(($P$4-J36)/D36)*0.001 -> 2.2238795 | S36: =(Q36+R36)/2 -> 2.2334204 | T36: =STDEV(Q36:R36) -> 0.013492862
A37: 6 | B37: 6.03 | C37: 0.1015 | D37: 0.1017 | E37: 0.022 | F37: 0.016 | G37: =E37*50 -> 1.1 | H37: =F37*50 -> 0.8 | I37: =(G37-0.0244)/0.1678 -> 6.4100119 | J37: =(H37-0.0244)/0.1678 -> 4.6221692 | K37: =(I37+J37)/2 -> 5.5160906 | L37: =STDEV(I37:J37) -> 1.2641957 | M37: =(($P$4-I37)/$P$4)*100 -> 97.268383 | N37: =(($P$4-J37)/$P$4)*100 -> 98.03027 | O37: =(M37+N37)/2 -> 97.649326 | P37: =STDEV(M37:N37) -> 0.53873505 | Q37: =(($P$4-I37)/C37)*0.001 -> 2.2487684 | R37: =(($P$4-J37)/D37)*0.001 -> 2.2619256 | S37: =(Q37+R37)/2 -> 2.255347 | T37: =STDEV(Q37:R37) -> 0.0093035576
A38: 8 | B38: 8.01 | C38: 0.101 | D38: 0.1006 | E38: 0.014 | F38: 0.013 | G38: =E38*50 -> 0.7 | H38: =F38*50 -> 0.65 | I38: =(G38-0.0244)/0.1678 -> 4.0262217 | J38: =(H38-0.0244)/0.1678 -> 3.7282479 | K38: =(I38+J38)/2 -> 3.8772348 | L38: =STDEV(I38:J38) -> 0.21069928 | M38: =(($P$4-I38)/$P$4)*100 -> 98.284232 | N38: =(($P$4-J38)/$P$4)*100 -> 98.411213 | O38: =(M38+N38)/2 -> 98.347722 | P38: =STDEV(M38:N38) -> 0.089789176 | Q38: =(($P$4-I38)/C38)*0.001 -> 2.2835028 | R38: =(($P$4-J38)/D38)*0.001 -> 2.2955443 | S38: =(Q38+R38)/2 -> 2.2895235 | T38: =STDEV(Q38:R38) -> 0.0085146262
A39: 10 | B39: 10.15 | C39: 0.1007 | D39: 0.1002 | E39: 0.012 | F39: 0.014 | G39: =E39*50 -> 0.6 | H39: =F39*50 -> 0.7 | I39: =(G39-0.0244)/0.1678 -> 3.4302741 | J39: =(H39-0.0244)/0.1678 -> 4.0262217 | K39: =(I39+J39)/2 -> 3.7282479 | L39: =STDEV(I39:J39) -> 0.42139856 | M39: =(($P$4-I39)/$P$4)*100 -> 98.538194 | N39: =(($P$4-J39)/$P$4)*100 -> 98.284232 | O39: =(M39+N39)/2 -> 98.411213 | P39: =STDEV(M39:N39) -> 0.17957835 | Q39: =(($P$4-I39)/C39)*0.001 -> 2.2962237 | R39: =(($P$4-J39)/D39)*0.001 -> 2.3017343 | S39: =(Q39+R39)/2 -> 2.298979 | T39: =STDEV(Q39:R39) -> 0.0038965979

Sheet Massa PALMA
N4: ABS | O4: ABS*VOL | P4: C. Teorica | Q4: C. Real
M5: sol 1 | N5: 0.701 | O5: =N5*50 -> 35.05 | P5: 200 | Q5: =(O5-0.0244)/0.1678 -> 208.73421 | T5: Y=0,1678x+0,0244
M6: sol. 2 | N6: 0.75 | O6: =N6*50 -> 37.5 | P6: 200 | Q6: =(O6-0.0244)/0.1678 -> 223.33492
M7: Sol.3 | N7: 0.788 | O7: =N7*50 -> 39.4 | P7: 200 | Q7: =(O7-0.0244)/0.1678 -> 234.65793
D9: Fibra Palma tratada com Ácido | I9: pH 10 | P9: V= | Q9: =20/1000 -> 0.02
B11: Valores das massas (mg) | D11: massa de semente (g) | F11: Absorbâncias (nm) | H11: Fator diluição | J11: Ce (ppm) | L11: Média (ppm) | M11: Desv P | N11: % Remoção | P11: Média % | Q11: Desvio Padrão | R11: QE (mg/g) | T11: Média | U11: Desv P
D12: m1 | E12: m2 | F12: abs1 | G12: abs2 | H12: abs 1 dil. | I12: abs 2 dil. | J12: [ ] 1 | K12: [ ] 2 | R12: 1 | S12: 2
B13: 50 | D13: 0.05 | E13: 0.0502 | F13: 0.047 | G13: 0.034 | H13: =F13*50 -> 2.35 | I13: =G13*50 -> 1.7 | J13: =(H13-0.0244)/0.1678 -> 13.859356 | K13: =(I13-0.0244)/0.1678 -> 9.9856973 | L13: =(J13+K13)/2 -> 11.922527 | M13: =STDEV(J13:K13) -> 2.7390906 | N13: =(($Q$5-J13)/$Q$5)*100 -> 93.360285 | O13: =(($Q$5-K13)/$Q$5)*100 -> 95.216071 | P13: =(N13+O13)/2 -> 94.288178 | Q13: =STDEV(N13:O13) -> 1.3122385 | R13: =(($Q$5-J13)/D13)*$Q$9 -> 77.94994 | S13: =(($Q$5-K13)/E13)*$Q$9 -> 79.182673 | T13: =(R13+S13)/2 -> 78.566307 | U13: =(S13+T13)/2 -> 78.87449
B14: 75 | D14: 0.0758 | E14: 0.0752 | F14: 0.109 | G14: 0.074 | H14: =F14*50 -> 5.45 | I14: =G14*50 -> 3.7 | J14: =(H14-0.0244)/0.1678 -> 32.333731 | K14: =(I14-0.0244)/0.1678 -> 21.904648 | L14: =(J14+K14)/2 -> 27.11919 | M14: =STDEV(J14:K14) -> 7.3744748 | N14: =(($Q$5-J14)/$Q$5)*100 -> 84.509616 | O14: =(($Q$5-K14)/$Q$5)*100 -> 89.505961 | Q14: =STDEV(N14:O14) -> 3.5329498 | R14: =(($Q$5-J14)/D14)*$Q$9 -> 46.543661 | S14: =(($Q$5-K14)/E14)*$Q$9 -> 49.688713 | T14: =(R14+S14)/2 -> 48.116187 | U14: =(S14+T14)/2 -> 48.90245
B15: 100 | D15: 0.1009 | E15: 0.1014 | F15: 0.525 | G15: 0.452 | H15: =F15*1 -> 0.525 | I15: =G15*1 -> 0.452 | J15: =(H15-0.0244)/0.1678 -> 2.9833135 | K15: =(I15-0.0244)/0.1678 -> 2.5482718 | L15: =(J15+K15)/2 -> 2.7657926 | M15: =STDEV(J15:K15) -> 0.30762095 | N15: =(($Q$5-J15)/$Q$5)*100 -> 98.57076 | O15: =(($Q$5-K15)/$Q$5)*100 -> 98.779179 | P15: =(N15+O15)/2 -> 98.674969 | Q15: =STDEV(N15:O15) -> 0.14737448 | R15: =(($Q$5-J15)/D15)*$Q$9 -> 40.783131 | S15: =(($Q$5-K15)/E15)*$Q$9 -> 40.667837 | T15: =(R15+S15)/2 -> 40.725484 | U15: =(S15+T15)/2 -> 40.696661
B16: 125 | D16: 0.1259 | E16: 0.1256 | F16: 0.023 | G16: 0.027 | H16: =F16*50 -> 1.15 | I16: =G16*50 -> 1.35 | J16: =(H16-0.0244)/0.1678 -> 6.7079857 | K16: =(I16-0.0244)/0.1678 -> 7.8998808 | L16: =(J16+K16)/2 -> 7.3039333 | M16: =STDEV(J16:K16) -> 0.84279712 | N16: =(($Q$5-J16)/$Q$5)*100 -> 96.786351 | O16: =(($Q$5-K16)/$Q$5)*100 -> 96.21534 | Q16: =STDEV(N16:O16) -> 0.40376569 | R16: =(($Q$5-J16)/D16)*$Q$9 -> 32.093125 | S16: =(($Q$5-K16)/E16)*$Q$9 -> 31.979988 | T16: =(R16+S16)/2 -> 32.036557 | U16: =(S16+T16)/2 -> 32.008272
B17: 150 | D17: 0.1519 | E17: 0.151 | F17: 0.297 | G17: 0.377 | H17: =F17*1 -> 0.297 | I17: =G17*1 -> 0.377 | J17: =(H17-0.0244)/0.1678 -> 1.624553 | K17: =(I17-0.0244)/0.1678 -> 2.1013111 | L17: =(J17+K17)/2 -> 1.8629321 | M17: =STDEV(J17:K17) -> 0.33711885 | N17: =(($Q$5-J17)/$Q$5)*100 -> 99.221712 | O17: =(($Q$5-K17)/$Q$5)*100 -> 98.993308 | P17: =(N17+O17)/2 -> 99.10751 | Q17: =STDEV(N17:O17) -> 0.16150628 | R17: =(($Q$5-J17)/D17)*$Q$9 -> 27.269211 | S17: =(($Q$5-K17)/E17)*$Q$9 -> 27.368596 | T17: =(R17+S17)/2 -> 27.318903 | U17: =(S17+T17)/2 -> 27.343749
B18: 175 | D18: 0.175 | E18: 0.1757 | F18: 0.023 | G18: 0.023 | H18: =F18*50 -> 1.15 | I18: =G18*50 -> 1.15 | J18: =(H18-0.0244)/0.1678 -> 6.7079857 | K18: =(I18-0.0244)/0.1678 -> 6.7079857 | L18: =(J18+K18)/2 -> 6.7079857 | M18: =STDEV(J18:K18) -> 0 | N18: =(($Q$5-J18)/$Q$5)*100 -> 96.786351 | O18: =(($Q$5-K18)/$Q$5)*100 -> 96.786351 | Q18: =STDEV(N18:O18) -> 0 | R18: =(($Q$5-J18)/D18)*$Q$9 -> 23.088711 | S18: =(($Q$5-K18)/E18)*$Q$9 -> 22.996724 | T18: =(R18+S18)/2 -> 23.042718 | U18: =(S18+T18)/2 -> 23.019721
B19: 200 | D19: 0.2002 | E19: 0.2013 | F19: 0.338 | G19: 0.38 | H19: =F19*1 -> 0.338 | I19: =G19*1 -> 0.38 | J19: =(H19-0.0244)/0.1678 -> 1.8688915 | K19: =(I19-0.0244)/0.1678 -> 2.1191895 | L19: =(J19+K19)/2 -> 1.9940405 | M19: =STDEV(J19:K19) -> 0.17698739 | N19: =(($Q$5-J19)/$Q$5)*100 -> 99.104655 | O19: =(($Q$5-K19)/$Q$5)*100 -> 98.984743 | P19: =(N19+O19)/2 -> 99.044699 | Q19: =STDEV(N19:O19) -> 0.084790795 | R19: =(($Q$5-J19)/D19)*$Q$9 -> 20.665866 | S19: =(($Q$5-K19)/E19)*$Q$9 -> 20.528069 | T19: =(R19+S19)/2 -> 20.596968 | U19: =(S19+T19)/2 -> 20.562518
D24: Fibra Palma tratada com Base | I24: pH 6
B26: Valores das massas (mg) | D26: massa de semente (g) | F26: Absorbâncias (nm) | H26: Fator diluição | J26: Concetração (ppm) | L26: Média (ppm) | M26: Desv P | N26: % Remoção | P26: Média % | Q26: Desvio Padrão | R26: QE (mg/g) | T26: Média | U26: Desv P
D27: m1 | E27: m2 | F27: abs1 | G27: abs2 | H27: abs 1 dil. | I27: abs 2 dil. | J27: [ ] 1 | K27: [ ] 2 | L27: concentração | R27: 1 | S27: 2
B28: 50 | D28: 0.0511 | E28: 0.0506 | F28: 0.041 | G28: 0.023 | H28: =F28*50 -> 2.05 | I28: =G28*50 -> 1.15 | J28: =(H28-0.0244)/0.1678 -> 12.071514 | K28: =(I28-0.0244)/0.1678 -> 6.7079857 | L28: =(J28+K28)/2 -> 9.3897497 | M28: =STDEV(J28:K28) -> 3.792587 | N28: =(($Q$5-J28)/$Q$5)*100 -> 94.216801 | O28: =(($Q$5-K28)/$Q$5)*100 -> 96.786351 | P28: =(N28+O28)/2 -> 95.501576 | Q28: =STDEV(N28:O28) -> 1.8169456 | R28: =(($Q$5-J28)/D28)*$Q$9 -> 76.9717 | S28: =(($Q$5-K28)/E28)*$Q$9 -> 79.852262 | T28: =(R28+S28)/2 -> 78.411981 | U28: =STDEV(R28:S28) -> 2.0368645
B29: 75 | D29: 0.0761 | E29: 0.0752 | F29: 0.02 | G29: 0.035 | H29: =F29*50 -> 1 | I29: =G29*50 -> 1.75 | J29: =(H29-0.0244)/0.1678 -> 5.8140644 | K29: =(I29-0.0244)/0.1678 -> 10.283671 | L29: =(J29+K29)/2 -> 8.0488677 | M29: =STDEV(J29:K29) -> 3.1604892 | N29: =(($Q$5-J29)/$Q$5)*100 -> 97.214609 | O29: =(($Q$5-K29)/$Q$5)*100 -> 95.073318 | Q29: =STDEV(N29:O29) -> 1.5141213 | R29: =(($Q$5-J29)/D29)*$Q$9 -> 53.329867 | S29: =(($Q$5-K29)/E29)*$Q$9 -> 52.779398 | T29: =(R29+S29)/2 -> 53.054632 | U29: =STDEV(R29:S29) -> 0.38924022
B30: 100 | D30: 0.1026 | E30: 0.1022 | F30: 0.459 | G30: 0.324 | H30: =F30*1 -> 0.459 | I30: =G30*1 -> 0.324 | J30: =(H30-0.0244)/0.1678 -> 2.5899881 | K30: =(I30-0.0244)/0.1678 -> 1.7854589 | L30: =(J30+K30)/2 -> 2.1877235 | M30: =STDEV(J30:K30) -> 0.56888805 | N30: =(($Q$5-J30)/$Q$5)*100 -> 98.759193 | O30: =(($Q$5-K30)/$Q$5)*100 -> 99.144626 | P30: =(N30+O30)/2 -> 98.951909 | Q30: =STDEV(N30:O30) -> 0.27254184 | R30: =(($Q$5-J30)/D30)*$Q$9 -> 40.184058 | S30: =(($Q$5-K30)/E30)*$Q$9 -> 40.498777 | T30: =(R30+S30)/2 -> 40.341417 | U30: =STDEV(R30:S30) -> 0.22253942
B31: 125 | D31: 0.1254 | E31: 0.1255 | F31: 0.018 | G31: 0.013 | H31: =F31*50 -> 0.9 | I31: =G31*50 -> 0.65 | J31: =(H31-0.0244)/0.1678 -> 5.2181168 | K31: =(I31-0.0244)/0.1678 -> 3.7282479 | L31: =(J31+K31)/2 -> 4.4731824 | M31: =STDEV(J31:K31) -> 1.0534964 | N31: =(($Q$5-J31)/$Q$5)*100 -> 97.500114 | O31: =(($Q$5-K31)/$Q$5)*100 -> 98.213878 | Q31: =STDEV(N31:O31) -> 0.50470712 | R31: =(($Q$5-J31)/D31)*$Q$9 -> 32.458707 | S31: =(($Q$5-K31)/E31)*$Q$9 -> 32.670272 | T31: =(R31+S31)/2 -> 32.56449 | U31: =STDEV(R31:S31) -> 0.14959961
B32: 150 | D32: 0.152 | E32: 0.152 | F32: 0.239 | G32: 0.255 | H32: =F32*1 -> 0.239 | I32: =G32*1 -> 0.255 | J32: =(H32-0.0244)/0.1678 -> 1.2789035 | K32: =(I32-0.0244)/0.1678 -> 1.3742551 | L32: =(J32+K32)/2 -> 1.3265793 | M32: =STDEV(J32:K32) -> 0.067423769 | N32: =(($Q$5-J32)/$Q$5)*100 -> 99.387305 | O32: =(($Q$5-K32)/$Q$5)*100 -> 99.341624 | P32: =(N32+O32)/2 -> 99.364465 | Q32: =STDEV(N32:O32) -> 0.032301255 | R32: =(($Q$5-J32)/D32)*$Q$9 -> 27.296751 | S32: =(($Q$5-K32)/E32)*$Q$9 -> 27.284204 | T32: =(R32+S32)/2 -> 27.290477 | U32: =STDEV(R32:S32) -> 0.0088715486
B33: 175 | D33: 0.1751 | E33: 0.1761 | F33: 0.019 | G33: 0.011 | H33: =F33*50 -> 0.95 | I33: =G33*50 -> 0.55 | J33: =(H33-0.0244)/0.1678 -> 5.5160906 | K33: =(I33-0.0244)/0.1678 -> 3.1323004 | L33: =(J33+K33)/2 -> 4.3241955 | M33: =STDEV(J33:K33) -> 1.6855942 | N33: =(($Q$5-J33)/$Q$5)*100 -> 97.357361 | O33: =(($Q$5-K33)/$Q$5)*100 -> 98.499383 | Q33: =STDEV(N33:O33) -> 0.80753138 | R33: =(($Q$5-J33)/D33)*$Q$9 -> 23.211664 | S33: =(($Q$5-K33)/E33)*$Q$9 -> 23.350586 | T33: =(R33+S33)/2 -> 23.281125 | U33: =STDEV(R33:S33) -> 0.098232594
B34: 200 | D34: 0.2045 | E34: 0.2028 | F34: 0.167 | G34: 0.161 | H34: =F34*1 -> 0.167 | I34: =G34*1 -> 0.161 | J34: =(H34-0.0244)/0.1678 -> 0.84982122 | K34: =(I34-0.0244)/0.1678 -> 0.81406436 | L34: =(J34+K34)/2 -> 0.83194279 | M34: =STDEV(J34:K34) -> 0.025283914 | N34: =(($Q$5-J34)/$Q$5)*100 -> 99.592869 | O34: =(($Q$5-K34)/$Q$5)*100 -> 99.61 | P34: =(N34+O34)/2 -> 99.601434 | Q34: =STDEV(N34:O34) -> 0.012112971 | R34: =(($Q$5-J34)/D34)*$Q$9 -> 20.330991 | S34: =(($Q$5-K34)/E34)*$Q$9 -> 20.504945 | T34: =(R34+S34)/2 -> 20.417968 | U34: =STDEV(R34:S34) -> 0.12300388
D38: Fibra Palma In Natura | H38: pH 10
B40: Valores das massas (mg) | D40: massa de semente (g) | F40: Absorbâncias (nm) | H40: Fator diluição | J40: Concetração (ppm) | L40: Média (ppm) | M40: Desvio Padrão | N40: % Remoção | P40: Média % | Q40: Desvio Padrão | R40: QE (mg/g) | T40: Média | U40: Desvio Padrão
D41: m1 | E41: m2 | F41: abs1 | G41: abs2 | H41: abs 1 dil. | I41: abs 2 dil. | J41: [ ] 1 | K41: [ ] 2 | L41: concentração | R41: 1 | S41: 2
B42: 50 | D42: 0.0502 | E42: 0.0517 | F42: 0.042 | G42: 0.03 | H42: =F42*50 -> 2.1 | I42: =G42*50 -> 1.5 | J42: =(H42-0.0244)/0.1678 -> 12.369487 | K42: =(I42-0.0244)/0.1678 -> 8.7938021 | L42: =(J42+K42)/2 -> 10.581645 | M42: =STDEV(J42:K42) -> 2.5283914 | N42: =(($Q$5-J42)/$Q$5)*100 -> 94.074049 | O42: =(($Q$5-K42)/$Q$5)*100 -> 95.787081 | P42: =(N42+O42)/2 -> 94.930565 | Q42: =STDEV(N42:O42) -> 1.2112971 | R42: =(($Q$5-J42)/D42)*$Q$9 -> 78.232956 | S42: =(($Q$5-K42)/E42)*$Q$9 -> 77.346385 | T42: =(R42+S42)/2 -> 77.789671 | U42: =STDEV(R42:S42) -> 0.62690046
B43: 75 | D43: 0.0761 | E43: 0.076 | F43: 0.056 | G43: 0.072 | H43: =F43*50 -> 2.8 | I43: =G43*50 -> 3.6 | J43: =(H43-0.0244)/0.1678 -> 16.54112 | K43: =(I43-0.0244)/0.1678 -> 21.308701 | L43: =(J43+K43)/2 -> 18.924911 | M43: =STDEV(J43:K43) -> 3.3711885 | N43: =(($Q$5-J43)/$Q$5)*100 -> 92.07551 | O43: =(($Q$5-K43)/$Q$5)*100 -> 89.791467 | Q43: =STDEV(N43:O43) -> 1.6150628 | R43: =(($Q$5-J43)/D43)*$Q$9 -> 50.510667 | S43: =(($Q$5-K43)/E43)*$Q$9 -> 49.322502 | T43: =(R43+S43)/2 -> 49.916584 | U43: =STDEV(R43:S43) -> 0.84015955
B44: 100 | D44: 0.102 | E44: 0.1006 | F44: 0.631 | G44: 0.744 | H44: =F44*1 -> 0.631 | I44: =G44*1 -> 0.744 | J44: =(H44-0.0244)/0.1678 -> 3.6150179 | K44: =(I44-0.0244)/0.1678 -> 4.2884386 | L44: =(J44+K44)/2 -> 3.9517282 | M44: =STDEV(J44:K44) -> 0.47618037 | N44: =(($Q$5-J44)/$Q$5)*100 -> 98.268124 | O44: =(($Q$5-K44)/$Q$5)*100 -> 97.945503 | P44: =(N44+O44)/2 -> 98.106813 | Q44: =STDEV(N44:O44) -> 0.22812762 | R44: =(($Q$5-J44)/D44)*$Q$9 -> 40.219449 | S44: =(($Q$5-K44)/E44)*$Q$9 -> 40.645282 | T44: =(R44+S44)/2 -> 40.432365 | U44: =STDEV(R44:S44) -> 0.3011095
B45: 125 | D45: 0.1255 | E45: 0.1254 | F45: 0.031 | G45: 0.024 | H45: =F45*50 -> 1.55 | I45: =G45*50 -> 1.2 | J45: =(H45-0.0244)/0.1678 -> 9.0917759 | K45: =(I45-0.0244)/0.1678 -> 7.0059595 | L45: =(J45+K45)/2 -> 8.0488677 | M45: =STDEV(J45:K45) -> 1.474895 | N45: =(($Q$5-J45)/$Q$5)*100 -> 95.644329 | O45: =(($Q$5-K45)/$Q$5)*100 -> 96.643598 | Q45: =STDEV(N45:O45) -> 0.70658996 | R45: =(($Q$5-J45)/D45)*$Q$9 -> 31.815527 | S45: =(($Q$5-K45)/E45)*$Q$9 -> 32.173564 | T45: =(R45+S45)/2 -> 31.994546 | U45: =STDEV(R45:S45) -> 0.25317063
B46: 150 | D46: 0.1532 | E46: 0.153 | F46: 0.491 | G46: 0.451 | H46: =F46*1 -> 0.491 | I46: =G46*1 -> 0.451 | J46: =(H46-0.0244)/0.1678 -> 2.7806913 | K46: =(I46-0.0244)/0.1678 -> 2.5423123 | L46: =(J46+K46)/2 -> 2.6615018 | M46: =STDEV(J46:K46) -> 0.16855942 | N46: =(($Q$5-J46)/$Q$5)*100 -> 98.667832 | O46: =(($Q$5-K46)/$Q$5)*100 -> 98.782034 | P46: =(N46+O46)/2 -> 98.724933 | Q46: =STDEV(N46:O46) -> 0.080753138 | R46: =(($Q$5-J46)/D46)*$Q$9 -> 26.886882 | S46: =(($Q$5-K46)/E46)*$Q$9 -> 26.953189 | T46: =(R46+S46)/2 -> 26.920035 | U46: =STDEV(R46:S46) -> 0.046886064
B47: 175 | D47: 0.1752 | E47: 0.1756 | F47: 0.018 | G47: 0.017 | H47: =F47*50 -> 0.9 | I47: =G47*50 -> 0.85 | J47: =(H47-0.0244)/0.1678 -> 5.2181168 | K47: =(I47-0.0244)/0.1678 -> 4.920143 | L47: =(J47+K47)/2 -> 5.0691299 | M47: =STDEV(J47:K47) -> 0.21069928 | N47: =(($Q$5-J47)/$Q$5)*100 -> 97.500114 | O47: =(($Q$5-K47)/$Q$5)*100 -> 97.642867 | Q47: =STDEV(N47:O47) -> 0.10094142 | R47: =(($Q$5-J47)/D47)*$Q$9 -> 23.23243 | S47: =(($Q$5-K47)/E47)*$Q$9 -> 23.213447 | T47: =(R47+S47)/2 -> 23.222939 | U47: =STDEV(R47:S47) -> 0.013423337
B48: 200 | D48: 0.2 | E48: 0.2 | F48: 0.484 | G48: 0.53 | H48: =F48*1 -> 0.484 | I48: =G48*1 -> 0.53 | J48: =(H48-0.0244)/0.1678 -> 2.738975 | K48: =(I48-0.0244)/0.1678 -> 3.0131108 | L48: =(J48+K48)/2 -> 2.8760429 | M48: =STDEV(J48:K48) -> 0.19384334 | N48: =(($Q$5-J48)/$Q$5)*100 -> 98.687817 | O48: =(($Q$5-K48)/$Q$5)*100 -> 98.556484 | P48: =(N48+O48)/2 -> 98.622151 | Q48: =STDEV(N48:O48) -> 0.092866109 | R48: =(($Q$5-J48)/D48)*$Q$9 -> 20.599523 | S48: =(($Q$5-K48)/E48)*$Q$9 -> 20.57211 | T48: =(R48+S48)/2 -> 20.585816 | U48: =STDEV(R48:S48) -> 0.019384334

Sheet Tempo PALMA
C2: Massa=100 mg | E2: =100*3 -> 300 | Q2: ABS | R2: ABS*VOL | T2: C. Teorico | U2: C. Real
M3: Y=0,1678x+0,0244 | P3: sol 4 | Q3: 0.677 | R3: =Q3*50 -> 33.85 | T3: 200 | U3: =(R3-0.0244)/0.1678 -> 201.58284
B4: Fibra Palma Ácido | F4: pH=10
Y5: 8h
B6: Tempo (min) | C6: massa de semente (g) | E6: Absorbâncias (nm) | G6: Fator diluição | I6: Ce (ppm) | K6: Média (ppm) | L6: DESV P | M6: % Remoção | O6: Média % | P6: DESV P | Q6: QE (mg/g) | S6: Média | T6: DESV P
C7: m1 | D7: m2 | E7: abs1 | F7: abs2 | G7: abs 1 dil. | H7: abs 2 dil. | I7: [ ] 1 | J7: [ ] 2 | Q7: 1 | R7: 2
B8: 0 | C8: 0.3053 | D8: 0.3033 | E8: 0.677 | F8: 0.677 | G8: =E8*50 -> 33.85 | H8: =F8*50 -> 33.85 | I8: =(G8-0.0244)/0.1678 -> 201.58284 | J8: =(H8-0.0244)/0.1678 -> 201.58284 | K8: =(I8+J8)/2 -> 201.58284 | L8: =STDEV(I8:J8) -> 0 | M8: =(($U$3-I8)/$U$3)*100 -> 0 | N8: =(($U$3-J8)/$U$3)*100 -> 0 | O8: =(M8+N8)/2 -> 0 | P8: =STDEV(M8:N8) -> 0 | Q8: =(($U$3-I8)/C8)*0.0244 -> 0 | R8: =(($U$3-J8)/D8)*0.0244 -> 0 | S8: =(Q8+R8)/2 -> 0 | T8: =STDEV(Q8:R8) -> 0
B9: 1 | C9: 0.3053 | D9: 0.3033 | E9: 0.534 | F9: 0.535 | G9: =E9*50 -> 26.7 | H9: =F9*50 -> 26.75 | I9: =(G9-0.0244)/0.1678 -> 158.97259 | J9: =(H9-0.0244)/0.1678 -> 159.27056 | K9: =(I9+J9)/2 -> 159.12157 | L9: =STDEV(I9:J9) -> 0.21069928 | M9: =(($U$3-I9)/$U$3)*100 -> 21.137836 | N9: =(($U$3-J9)/$U$3)*100 -> 20.990019 | O9: =(M9+N9)/2 -> 21.063928 | P9: =STDEV(M9:N9) -> 0.10452243 | Q9: =(($U$3-I9)/C9)*0.0244 -> 3.4054704 | R9: =(($U$3-J9)/D9)*0.0244 -> 3.403955 | S9: =(Q9+R9)/2 -> 3.4047127 | T9: =STDEV(Q9:R9) -> 0.0010715464
B10: 5 | C10: 0.3053 | D10: 0.3033 | E10: 0.506 | F10: 0.511 | G10: =E10*50 -> 25.3 | H10: =F10*50 -> 25.55 | I10: =(G10-0.0244)/0.1678 -> 150.62932 | J10: =(H10-0.0244)/0.1678 -> 152.11919 | K10: =(I10+J10)/2 -> 151.37426 | L10: =STDEV(I10:J10) -> 1.0534964 | M10: =(($U$3-I10)/$U$3)*100 -> 25.276713 | N10: =(($U$3-J10)/$U$3)*100 -> 24.537628 | O10: =(M10+N10)/2 -> 24.907171 | P10: =STDEV(M10:N10) -> 0.52261215 | Q10: =(($U$3-I10)/C10)*0.0244 -> 4.0722758 | R10: =(($U$3-J10)/D10)*0.0244 -> 3.9792713 | S10: =(Q10+R10)/2 -> 4.0257735 | T10: =STDEV(Q10:R10) -> 0.065764077
B11: 10 | C11: 0.3053 | D11: 0.3033 | E11: 0.46 | F11: 0.465 | G11: =E11*50 -> 23 | H11: =F11*50 -> 23.25 | I11: =(G11-0.0244)/0.1678 -> 136.92253 | J11: =(H11-0.0244)/0.1678 -> 138.4124 | K11: =(I11+J11)/2 -> 137.66746 | L11: =STDEV(I11:J11) -> 1.0534964 | M11: =(($U$3-I11)/$U$3)*100 -> 32.076297 | N11: =(($U$3-J11)/$U$3)*100 -> 31.337212 | O11: =(M11+N11)/2 -> 31.706755 | P11: =STDEV(M11:N11) -> 0.52261215 | Q11: =(($U$3-I11)/C11)*0.0244 -> 5.1677418 | R11: =(($U$3-J11)/D11)*0.0244 -> 5.081961 | S11: =(Q11+R11)/2 -> 5.1248514 | T11: =STDEV(Q11:R11) -> 0.060656187
B12: 30 | C12: 0.3053 | D12: 0.3033 | E12: 0.363 | F12: 0.382 | G12: =E12*50 -> 18.15 | H12: =F12*50 -> 19.1 | I12: =(G12-0.0244)/0.1678 -> 108.01907 | J12: =(H12-0.0244)/0.1678 -> 113.68057 | K12: =(I12+J12)/2 -> 110.84982 | L12: =STDEV(I12:J12) -> 4.0032863 | M12: =(($U$3-I12)/$U$3)*100 -> 46.41455 | N12: =(($U$3-J12)/$U$3)*100 -> 43.606026 | O12: =(M12+N12)/2 -> 45.010288 | P12: =STDEV(M12:N12) -> 1.9859262 | Q12: =(($U$3-I12)/C12)*0.0244 -> 7.4777462 | R12: =(($U$3-J12)/D12)*0.0244 -> 7.0715966 | S12: =(Q12+R12)/2 -> 7.2746714 | T12: =STDEV(Q12:R12) -> 0.28719108
B13: 60 | C13: 0.3053 | D13: 0.3033 | E13: 0.267 | F13: 0.266 | G13: =E13*50 -> 13.35 | H13: =F13*50 -> 13.3 | I13: =(G13-0.0244)/0.1678 -> 79.413588 | J13: =(H13-0.0244)/0.1678 -> 79.115614 | K13: =(I13+J13)/2 -> 79.264601 | L13: =STDEV(I13:J13) -> 0.21069928 | M13: =(($U$3-I13)/$U$3)*100 -> 60.604986 | N13: =(($U$3-J13)/$U$3)*100 -> 60.752803 | O13: =(M13+N13)/2 -> 60.678894 | P13: =STDEV(M13:N13) -> 0.10452243 | Q13: =(($U$3-I13)/C13)*0.0244 -> 9.7639361 | R13: =(($U$3-J13)/D13)*0.0244 -> 9.8522922 | S13: =(Q13+R13)/2 -> 9.8081142 | T13: =STDEV(Q13:R13) -> 0.062477261
B14: 90 | C14: 0.3053 | D14: 0.3033 | E14: 0.21 | F14: 0.213 | G14: =E14*50 -> 10.5 | H14: =F14*50 -> 10.65 | I14: =(G14-0.0244)/0.1678 -> 62.429082 | J14: =(H14-0.0244)/0.1678 -> 63.323004 | K14: =(I14+J14)/2 -> 62.876043 | L14: =STDEV(I14:J14) -> 0.63209784 | M14: =(($U$3-I14)/$U$3)*100 -> 69.030557 | N14: =(($U$3-J14)/$U$3)*100 -> 68.587106 | O14: =(M14+N14)/2 -> 68.808831 | P14: =STDEV(M14:N14) -> 0.31356729 | Q14: =(($U$3-I14)/C14)*0.0244 -> 11.121361 | R14: =(($U$3-J14)/D14)*0.0244 -> 11.122782 | S14: =(Q14+R14)/2 -> 11.122072 | T14: =STDEV(Q14:R14) -> 0.0010049217
B15: 120 | C15: 0.3053 | D15: 0.3033 | E15: 0.17 | F15: 0.166 | G15: =E15*50 -> 8.5 | H15: =F15*50 -> 8.3 | I15: =(G15-0.0244)/0.1678 -> 50.510131 | J15: =(H15-0.0244)/0.1678 -> 49.318236 | K15: =(I15+J15)/2 -> 49.914184 | L15: =STDEV(I15:J15) -> 0.84279712 | M15: =(($U$3-I15)/$U$3)*100 -> 74.943238 | N15: =(($U$3-J15)/$U$3)*100 -> 75.534506 | O15: =(M15+N15)/2 -> 75.238872 | P15: =STDEV(M15:N15) -> 0.41808972 | Q15: =(($U$3-I15)/C15)*0.0244 -> 12.07394 | R15: =(($U$3-J15)/D15)*0.0244 -> 12.249444 | S15: =(Q15+R15)/2 -> 12.161692 | T15: =STDEV(Q15:R15) -> 0.12409951
B16: 180 | C16: 0.3053 | D16: 0.3033 | E16: 0.105 | F16: 0.13 | G16: =E16*50 -> 5.25 | H16: =F16*50 -> 6.5 | I16: =(G16-0.0244)/0.1678 -> 31.141836 | J16: =(H16-0.0244)/0.1678 -> 38.59118 | K16: =(I16+J16)/2 -> 34.866508 | L16: =STDEV(I16:J16) -> 5.267482 | M16: =(($U$3-I16)/$U$3)*100 -> 84.551346 | N16: =(($U$3-J16)/$U$3)*100 -> 80.85592 | O16: 82 | P16: =STDEV(M16:N16) -> 2.6130607 | Q16: =(($U$3-I16)/C16)*0.0244 -> 13.621882 | R16: =(($U$3-J16)/D16)*0.0244 -> 13.112418 | S16: =(Q16+R16)/2 -> 13.36715 | T16: =STDEV(Q16:R16) -> 0.36024501
B17: 240 | C17: 0.3053 | D17: 0.3033 | E17: 0.092 | F17: 0.089 | G17: =E17*50 -> 4.6 | H17: =F17*50 -> 4.45 | I17: =(G17-0.0244)/0.1678 -> 27.268176 | J17: =(H17-0.0244)/0.1678 -> 26.374255 | K17: =(I17+J17)/2 -> 26.821216 | L17: =STDEV(I17:J17) -> 0.63209784 | M17: =(($U$3-I17)/$U$3)*100 -> 86.472967 | N17: =(($U$3-J17)/$U$3)*100 -> 86.916418 | O17: =(M17+N17)/2 -> 86.694693 | P17: =STDEV(M17:N17) -> 0.31356729 | Q17: =(($U$3-I17)/C17)*0.0244 -> 13.93147 | R17: =(($U$3-J17)/D17)*0.0244 -> 14.09525 | S17: =(Q17+R17)/2 -> 14.01336 | T17: =STDEV(Q17:R17) -> 0.11581029
B18: 300 | C18: 0.3053 | D18: 0.3033 | E18: 0.076 | F18: 0.074 | G18: =E18*50 -> 3.8 | H18: =F18*50 -> 3.7 | I18: =(G18-0.0244)/0.1678 -> 22.500596 | J18: =(H18-0.0244)/0.1678 -> 21.904648 | K18: =(I18+J18)/2 -> 22.202622 | L18: =STDEV(I18:J18) -> 0.42139856 | M18: =(($U$3-I18)/$U$3)*100 -> 88.83804 | N18: =(($U$3-J18)/$U$3)*100 -> 89.133674 | O18: =(M18+N18)/2 -> 88.985857 | P18: =STDEV(M18:N18) -> 0.20904486 | Q18: =(($U$3-I18)/C18)*0.0244 -> 14.312501 | R18: =(($U$3-J18)/D18)*0.0244 -> 14.454823 | S18: =(Q18+R18)/2 -> 14.383662 | T18: =STDEV(Q18:R18) -> 0.10063653
B19: 360 | C19: 0.3053 | D19: 0.3033 | E19: 0.066 | F19: 0.073 | G19: =E19*50 -> 3.3 | H19: =F19*50 -> 3.65 | I19: =(G19-0.0244)/0.1678 -> 19.520858 | J19: =(H19-0.0244)/0.1678 -> 21.606675 | K19: =(I19+J19)/2 -> 20.563766 | L19: =STDEV(I19:J19) -> 1.474895 | M19: =(($U$3-I19)/$U$3)*100 -> 90.31621 | N19: =(($U$3-J19)/$U$3)*100 -> 89.281491 | O19: =(M19+N19)/2 -> 89.798851 | P19: =STDEV(M19:N19) -> 0.73165701 | Q19: =(($U$3-I19)/C19)*0.0244 -> 14.550646 | R19: =(($U$3-J19)/D19)*0.0244 -> 14.478794 | S19: =(Q19+R19)/2 -> 14.51472 | T19: =STDEV(Q19:R19) -> 0.050806844
B20: 480 | C20: 0.3053 | D20: 0.3033 | E20: 0.056 | F20: 0.059 | G20: =E20*50 -> 2.8 | H20: =F20*50 -> 2.95 | I20: =(G20-0.0244)/0.1678 -> 16.54112 | J20: =(H20-0.0244)/0.1678 -> 17.435042 | K20: =(I20+J20)/2 -> 16.988081 | L20: =STDEV(I20:J20) -> 0.63209784 | M20: =(($U$3-I20)/$U$3)*100 -> 91.794381 | N20: =(($U$3-J20)/$U$3)*100 -> 91.350929 | O20: =(M20+N20)/2 -> 91.572655 | P20: =STDEV(M20:N20) -> 0.31356729 | Q20: =(($U$3-I20)/C20)*0.0244 -> 14.788791 | R20: =(($U$3-J20)/D20)*0.0244 -> 14.814396 | S20: =(Q20+R20)/2 -> 14.801593 | T20: =STDEV(Q20:R20) -> 0.018105247
B21: 1440 | C21: 0.3053 | D21: 0.3033 | E21: 0.053 | F21: 0.052 | G21: =E21*50 -> 2.65 | H21: =F21*50 -> 2.6 | I21: =(G21-0.0244)/0.1678 -> 15.647199 | J21: =(H21-0.0244)/0.1678 -> 15.349225 | K21: =(I21+J21)/2 -> 15.498212 | L21: =STDEV(I21:J21) -> 0.21069928 | M21: =(($U$3-I21)/$U$3)*100 -> 92.237832 | N21: =(($U$3-J21)/$U$3)*100 -> 92.385649 | O21: =(M21+N21)/2 -> 92.31174 | P21: =STDEV(M21:N21) -> 0.10452243 | Q21: =(($U$3-I21)/C21)*0.0244 -> 14.860234 | R21: =(($U$3-J21)/D21)*0.0244 -> 14.982196 | S21: =(Q21+R21)/2 -> 14.921215 | T21: =STDEV(Q21:R21) -> 0.086240051
B26: Fibra Palma Base | F26: pH=6
Y27: 4h
B28: Tempo (min) | C28: massa de semente (g) | E28: Absorbâncias (nm) | G28: Fator diluição | I28: Ce (ppm) | K28: Média (ppm) | L28: DESV P | M28: % Remoção | O28: Média % | P28: DESV P | Q28: QE (mg/g) | S28: Média | T28: DESV P
C29: m1 | D29: m2 | E29: abs1 | F29: abs2 | G29: abs 1 dil. | H29: abs 2 dil. | I29: [ ] 1 | J29: [ ] 2 | Q29: 1 | R29: 2
B30: 0 | C30: 0.3007 | D30: 0.301 | E30: 0.677 | F30: 0.677 | G30: =E30*50 -> 33.85 | H30: =F30*50 -> 33.85 | I30: =(G30-0.0244)/0.1678 -> 201.58284 | J30: =(H30-0.0244)/0.1678 -> 201.58284 | K30: =(I30+J30)/2 -> 201.58284 | L30: =STDEV(I30:J30) -> 0 | M30: =(($U$3-I30)/$U$3)*100 -> 0 | N30: =(($U$3-J30)/$U$3)*100 -> 0 | O30: =(M30+N30)/2 -> 0 | P30: =STDEV(M30:N30) -> 0 | Q30: =(($R$3-I30)/C30)*0.0244 -> -13.610513 | R30: =(($R$3-J30)/D30)*0.0244 -> -13.596948 | S30: =(Q30+R30)/2 -> -13.60373 | T30: =STDEV(Q30:R30) -> 0.0095921122
B31: 1 | C31: 0.3007 | D31: 0.301 | E31: 0.466 | F31: 0.468 | G31: =E31*50 -> 23.3 | H31: =F31*50 -> 23.4 | I31: =(G31-0.0244)/0.1678 -> 138.71037 | J31: =(H31-0.0244)/0.1678 -> 139.30632 | K31: =(I31+J31)/2 -> 139.00834 | L31: =STDEV(I31:J31) -> 0.42139856 | M31: =(($U$3-I31)/$U$3)*100 -> 31.189395 | N31: =(($U$3-J31)/$U$3)*100 -> 30.893761 | O31: =(M31+N31)/2 -> 31.041578 | P31: =STDEV(M31:N31) -> 0.20904486 | Q31: =(($R$3-I31)/C31)*0.0244 -> -8.5087895 | R31: =(($R$3-J31)/D31)*0.0244 -> -8.5486184 | S31: =(Q31+R31)/2 -> -8.528704 | T31: =STDEV(Q31:R31) -> 0.028163249
B32: 5 | C32: 0.3007 | D32: 0.301 | E32: 0.395 | F32: 0.376 | G32: =E32*50 -> 19.75 | H32: =F32*50 -> 18.8 | I32: =(G32-0.0244)/0.1678 -> 117.55423 | J32: =(H32-0.0244)/0.1678 -> 111.89273 | K32: =(I32+J32)/2 -> 114.72348 | L32: =STDEV(I32:J32) -> 4.0032863 | M32: =(($U$3-I32)/$U$3)*100 -> 41.684405 | N32: =(($U$3-J32)/$U$3)*100 -> 44.492928 | O32: =(M32+N32)/2 -> 43.088667 | P32: =STDEV(M32:N32) -> 1.9859262 | Q32: =(($R$3-I32)/C32)*0.0244 -> -6.7920959 | R32: =(($R$3-J32)/D32)*0.0244 -> -6.3263874 | S32: =(Q32+R32)/2 -> -6.5592416 | T32: =STDEV(Q32:R32) -> 0.32930567
B33: 10 | C33: 0.3007 | D33: 0.301 | E33: 0.26 | F33: 0.195 | G33: =E33*50 -> 13 | H33: =F33*50 -> 9.75 | I33: =(G33-0.0244)/0.1678 -> 77.327771 | J33: =(H33-0.0244)/0.1678 -> 57.959476 | K33: =(I33+J33)/2 -> 67.643623 | L33: =STDEV(I33:J33) -> 13.695453 | M33: =(($U$3-I33)/$U$3)*100 -> 61.639705 | N33: =(($U$3-J33)/$U$3)*100 -> 71.247812 | O33: =(M33+N33)/2 -> 66.443759 | P33: =STDEV(M33:N33) -> 6.7939579 | Q33: =(($R$3-I33)/C33)*0.0244 -> -3.5279601 | R33: =(($R$3-J33)/D33)*0.0244 -> -1.9543894 | S33: =(Q33+R33)/2 -> -2.7411748 | T33: =STDEV(Q33:R33) -> 1.1126826
B34: 30 | C34: 0.3007 | D34: 0.301 | E34: 0.133 | F34: 0.079 | G34: =E34*50 -> 6.65 | H34: =F34*50 -> 3.95 | I34: =(G34-0.0244)/0.1678 -> 39.485101 | J34: =(H34-0.0244)/0.1678 -> 23.394517 | K34: =(I34+J34)/2 -> 31.439809 | L34: =STDEV(I34:J34) -> 11.377761 | M34: =(($U$3-I34)/$U$3)*100 -> 80.412469 | N34: =(($U$3-J34)/$U$3)*100 -> 88.394589 | O34: =(M34+N34)/2 -> 84.403529 | P34: =STDEV(M34:N34) -> 5.6442112 | Q34: =(($R$3-I34)/C34)*0.0244 -> -0.45725465 | R34: =(($R$3-J34)/D34)*0.0244 -> 0.84755408 | S34: =(Q34+R34)/2 -> 0.19514972 | T34: =STDEV(Q34:R34) -> 0.9226391
B35: 60 | C35: 0.3007 | D35: 0.301 | E35: 0.056 | F35: 0.042 | G35: =E35*50 -> 2.8 | H35: =F35*50 -> 2.1 | I35: =(G35-0.0244)/0.1678 -> 16.54112 | J35: =(H35-0.0244)/0.1678 -> 12.369487 | K35: =(I35+J35)/2 -> 14.455304 | L35: =STDEV(I35:J35) -> 2.9497899 | M35: =(($U$3-I35)/$U$3)*100 -> 91.794381 | N35: =(($U$3-J35)/$U$3)*100 -> 93.863819 | O35: =(M35+N35)/2 -> 92.8291 | P35: =STDEV(M35:N35) -> 1.463314 | Q35: =(($R$3-I35)/C35)*0.0244 -> 1.4045117 | R35: =(($R$3-J35)/D35)*0.0244 -> 1.7412774 | S35: =(Q35+R35)/2 -> 1.5728946 | T35: =STDEV(Q35:R35) -> 0.23812934
B36: 90 | C36: 0.3007 | D36: 0.301 | E36: 0.046 | F36: 0.039 | G36: =E36*50 -> 2.3 | H36: =F36*50 -> 1.95 | I36: =(G36-0.0244)/0.1678 -> 13.561383 | J36: =(H36-0.0244)/0.1678 -> 11.475566 | K36: =(I36+J36)/2 -> 12.518474 | L36: =STDEV(I36:J36) -> 1.474895 | M36: =(($U$3-I36)/$U$3)*100 -> 93.272551 | N36: =(($U$3-J36)/$U$3)*100 -> 94.30727 | O36: =(M36+N36)/2 -> 93.789911 | P36: =STDEV(M36:N36) -> 0.73165701 | Q36: =(($R$3-I36)/C36)*0.0244 -> 1.6462995 | R36: =(($R$3-J36)/D36)*0.0244 -> 1.8137415 | S36: =(Q36+R36)/2 -> 1.7300205 | T36: =STDEV(Q36:R36) -> 0.11839935
B37: 120 | C37: 0.3007 | D37: 0.301 | E37: 0.04 | F37: 0.032 | G37: =E37*50 -> 2 | H37: =F37*50 -> 1.6 | I37: =(G37-0.0244)/0.1678 -> 11.77354 | J37: =(H37-0.0244)/0.1678 -> 9.3897497 | K37: =(I37+J37)/2 -> 10.581645 | L37: =STDEV(I37:J37) -> 1.6855942 | M37: =(($U$3-I37)/$U$3)*100 -> 94.159453 | N37: =(($U$3-J37)/$U$3)*100 -> 95.341989 | O37: =(M37+N37)/2 -> 94.750721 | P37: =STDEV(M37:N37) -> 0.83617944 | Q37: =(($R$3-I37)/C37)*0.0244 -> 1.7913722 | R37: =(($R$3-J37)/D37)*0.0244 -> 1.9828243 | S37: =(Q37+R37)/2 -> 1.8870982 | T37: =STDEV(Q37:R37) -> 0.13537705
B38: 180 | C38: 0.3007 | D38: 0.301 | E38: 0.033 | F38: 0.023 | G38: =E38*50 -> 1.65 | H38: =F38*50 -> 1.15 | I38: =(G38-0.0244)/0.1678 -> 9.6877235 | J38: =(H38-0.0244)/0.1678 -> 6.7079857 | K38: =(I38+J38)/2 -> 8.1978546 | L38: =STDEV(I38:J38) -> 2.1069928 | M38: =(($U$3-I38)/$U$3)*100 -> 95.194172 | N38: =(($U$3-J38)/$U$3)*100 -> 96.672343 | O38: =(M38+N38)/2 -> 95.933258 | P38: =STDEV(M38:N38) -> 1.0452243 | Q38: =(($R$3-I38)/C38)*0.0244 -> 1.9606237 | R38: =(($R$3-J38)/D38)*0.0244 -> 2.2002164 | S38: =(Q38+R38)/2 -> 2.0804201 | T38: =STDEV(Q38:R38) -> 0.16941765
B39: 240 | C39: 0.3007 | D39: 0.301 | E39: 0.024 | F39: 0.021 | G39: =E39*50 -> 1.2 | H39: =F39*50 -> 1.05 | I39: =(G39-0.0244)/0.1678 -> 7.0059595 | J39: =(H39-0.0244)/0.1678 -> 6.1120381 | K39: =(I39+J39)/2 -> 6.5589988 | L39: =STDEV(I39:J39) -> 0.63209784 | M39: =(($U$3-I39)/$U$3)*100 -> 96.524526 | N39: =(($U$3-J39)/$U$3)*100 -> 96.967977 | O39: =(M39+N39)/2 -> 96.746251 | P39: =STDEV(M39:N39) -> 0.31356729 | Q39: =(($R$3-I39)/C39)*0.0244 -> 2.1782328 | R39: =(($R$3-J39)/D39)*0.0244 -> 2.2485258 | S39: =(Q39+R39)/2 -> 2.2133793 | T39: =STDEV(Q39:R39) -> 0.049704699
B40: 300 | C40: 0.3007 | D40: 0.301 | E40: 0.021 | F40: 0.017 | G40: =E40*50 -> 1.05 | H40: =F40*50 -> 0.85 | I40: =(G40-0.0244)/0.1678 -> 6.1120381 | J40: =(H40-0.0244)/0.1678 -> 4.920143 | K40: =(I40+J40)/2 -> 5.5160906 | L40: =STDEV(I40:J40) -> 0.84279712 | M40: =(($U$3-I40)/$U$3)*100 -> 96.967977 | N40: =(($U$3-J40)/$U$3)*100 -> 97.559245 | O40: =(M40+N40)/2 -> 97.263611 | P40: =STDEV(M40:N40) -> 0.41808972 | Q40: =(($R$3-I40)/C40)*0.0244 -> 2.2507691 | R40: =(($R$3-J40)/D40)*0.0244 -> 2.3451446 | S40: =(Q40+R40)/2 -> 2.2979568 | T40: =STDEV(Q40:R40) -> 0.06673352
B41: 360 | C41: 0.3007 | D41: 0.301 | E41: 0.022 | F41: 0.019 | G41: =E41*50 -> 1.1 | H41: =F41*50 -> 0.95 | I41: =(G41-0.0244)/0.1678 -> 6.4100119 | J41: =(H41-0.0244)/0.1678 -> 5.5160906 | K41: =(I41+J41)/2 -> 5.9630513 | L41: =STDEV(I41:J41) -> 0.63209784 | M41: =(($U$3-I41)/$U$3)*100 -> 96.82016 | N41: =(($U$3-J41)/$U$3)*100 -> 97.263611 | O41: =(M41+N41)/2 -> 97.041885 | P41: =STDEV(M41:N41) -> 0.31356729 | Q41: =(($R$3-I41)/C41)*0.0244 -> 2.2265903 | R41: =(($R$3-J41)/D41)*0.0244 -> 2.2968352 | S41: =(Q41+R41)/2 -> 2.2617128 | T41: =STDEV(Q41:R41) -> 0.049670618
B42: 480 | C42: 0.3007 | D42: 0.301 | E42: 0.021 | F42: 0.016 | G42: =E42*50 -> 1.05 | H42: =F42*50 -> 0.8 | I42: =(G42-0.0244)/0.1678 -> 6.1120381 | J42: =(H42-0.0244)/0.1678 -> 4.6221692 | K42: =(I42+J42)/2 -> 5.3671037 | L42: =STDEV(I42:J42) -> 1.0534964 | M42: =(($U$3-I42)/$U$3)*100 -> 96.967977 | N42: =(($U$3-J42)/$U$3)*100 -> 97.707062 | O42: =(M42+N42)/2 -> 97.33752 | P42: =STDEV(M42:N42) -> 0.52261215 | Q42: =(($R$3-I42)/C42)*0.0244 -> 2.2507691 | R42: =(($R$3-J42)/D42)*0.0244 -> 2.3692992 | S42: =(Q42+R42)/2 -> 2.3100342 | T42: =STDEV(Q42:R42) -> 0.083813461
B43: 1440 | C43: 0.3007 | D43: 0.301 | E43: 0.017 | F43: 0.015 | G43: =E43*50 -> 0.85 | H43: =F43*50 -> 0.75 | I43: =(G43-0.0244)/0.1678 -> 4.920143 | J43: =(H43-0.0244)/0.1678 -> 4.3241955 | K43: =(I43+J43)/2 -> 4.6221692 | L43: =STDEV(I43:J43) -> 0.42139856 | M43: =(($U$3-I43)/$U$3)*100 -> 97.559245 | N43: =(($U$3-J43)/$U$3)*100 -> 97.854879 | O43: =(M43+N43)/2 -> 97.707062 | P43: =STDEV(M43:N43) -> 0.20904486 | Q43: =(($R$3-I43)/C43)*0.001 -> 0.09620837 | R43: =(($R$3-J43)/D43)*0.001 -> 0.098092374 | S43: =(Q43+R43)/2 -> 0.097150372 | T43: =STDEV(Q43:R43) -> 0.0013321916
B48: Fibra Palma In Natura | F48: pH=10 | Y48: 8h
B50: Tempo (min) | C50: massa de semente (g) | E50: Absorbâncias (nm) | G50: Fator diluição | I50: Ce (ppm) | K50: Média (ppm) | L50: DESV P | M50: % Remoção | O50: Média % | P50: DESV P | Q50: QE (mg/g) | S50: Média | T50: DESV P
...

Sheet Conc. e temp PALMA
J1: ph 7 | O1: ph 10 | T1: ph 10
G2: ABS | H2: ABS*VOL | I2: C. Teorica | J2: C. Real | L2: ABS | M2: ABS*VOL | N2: C. Teorica | O2: C. Real | Q2: ABS | R2: ABS*VOL | S2: C. Teorica | T2: C. Real | U2: C. Teorica | V2: média C
G3: 0.292 | H3: =G3*50 -> 14.6 | I3: 100 | J3: =(H3-0.0244)/0.1678 -> 86.862932 | L3: 0.309 | M3: =L3*50 -> 15.45 | N3: 100 | O3: =(M3-0.0244)/0.1678 -> 91.928486 | Q3: 0.312 | R3: =Q3*50 -> 15.6 | S3: 100 | T3: =(R3-0.0244)/0.1678 -> 92.822408 | U3: 100 | V3: =AVERAGE(J3,O3,T3) -> 90.537942
B4: Isotermas | G4: 0.657 | H4: =G4*50 -> 32.85 | I4: 200 | J4: =(H4-0.0244)/0.1678 -> 195.62336 | L4: 0.668 | M4: =L4*50 -> 33.4 | N4: 200 | O4: =(M4-0.0244)/0.1678 -> 198.90107 | Q4: 0.672 | R4: =Q4*50 -> 33.6 | S4: 200 | T4: =(R4-0.0244)/0.1678 -> 200.09297 | U4: 200 | V4: =AVERAGE(J4,O4,T4) -> 198.2058
G5: 0.875 | H5: =G5*50 -> 43.75 | I5: 300 | J5: =(H5-0.0244)/0.1678 -> 260.58164 | L5: 0.953 | M5: =L5*50 -> 47.65 | N5: 300 | O5: =(M5-0.0244)/0.1678 -> 283.8236 | Q5: 0.916 | R5: =Q5*50 -> 45.8 | S5: 300 | T5: =(R5-0.0244)/0.1678 -> 272.79857 | U5: 300 | V5: =AVERAGE(J5,O5,T5) -> 272.40127
G6: 1.19 | H6: =G6*50 -> 59.5 | I6: 400 | J6: =(H6-0.0244)/0.1678 -> 354.44338 | L6: 1.154 | M6: =L6*50 -> 57.7 | N6: 400 | O6: =(M6-0.0244)/0.1678 -> 343.71633 | Q6: 1.325 | R6: =Q6*50 -> 66.25 | S6: 400 | T6: =(R6-0.0244)/0.1678 -> 394.66985 | U6: 400 | V6: =AVERAGE(J6,O6,T6) -> 364.27652
B11: 15 ºC | L11: Y=0,1678x+0,0244
B12: Fibra da Palma tratada com Base (NaOH)
B14: Concentrações | C14: massa de semente (g) | E14: Absorbâncias (nm) | G14: Fator diluição | I14: Ce (ppm) | K14: Ce Média (ppm) | L14: % Remoção | N14: Média % | O14: Desv P | P14: QE (mg/g) | R14: Qe Média | S14: Desv P
B15: 100 | C15: 0.1 | D15: 0.1 | E15: 0.002 | F15: 0.003 | G15: =E15*50 -> 0.1 | H15: =F15*50 -> 0.15 | I15: 1.01 | J15: 1.01 | K15: =(I15+J15)/2 -> 1.01 | L15: =(($V$3-I15)/$V$3)*100 -> 98.884446 | M15: =(($V$3-J15)/$V$3)*100 -> 98.884446 | N15: =(L15+M15)/2 -> 98.884446 | O15: =STDEV(L15:M15) -> 0 | P15: =(($V$3-I15)/C15)*0.02 -> 17.905588 | Q15: =(($V$3-J15)/D15)*0.02 -> 17.905588 | R15: =(P15+Q15)/2 -> 17.905588 | S15: =STDEV(P15:Q15) -> 0
B16: 200 | C16: 0.1 | D16: 0.1 | E16: 0.013 | F16: 0.017 | G16: =E16*50 -> 0.65 | H16: =F16*50 -> 0.85 | I16: =(G16-0.0244)/0.1678 -> 3.7282479 | J16: =(H16-0.0244)/0.1678 -> 4.920143 | K16: =(I16+J16)/2 -> 4.3241955 | L16: =(($V$4-I16)/$V$4)*100 -> 98.119002 | M16: =(($V$4-J16)/$V$4)*100 -> 97.517659 | N16: =(L16+M16)/2 -> 97.818331 | O16: =STDEV(L16:M16) -> 0.42521314 | P16: =(($V$4-I16)/C16)*0.02 -> 38.895511 | Q16: =(($V$4-J16)/D16)*0.02 -> 38.657132 | R16: =(P16+Q16)/2 -> 38.776321 | S16: =STDEV(P16:Q16) -> 0.16855942
B17: 300 | C17: 0.1 | D17: 0.1 | E17: 0.105 | F17: 0.113 | G17: =E17*50 -> 5.25 | H17: =F17*50 -> 5.65 | I17: =(G17-0.0244)/0.1678 -> 31.141836 | J17: =(H17-0.0244)/0.1678 -> 33.525626 | K17: =(I17+J17)/2 -> 32.333731 | L17: =(($V$5-I17)/$V$5)*100 -> 88.567661 | M17: =(($V$5-J17)/$V$5)*100 -> 87.692559 | N17: =(L17+M17)/2 -> 88.13011 | O17: =STDEV(L17:M17) -> 0.61879088 | P17: =(($V$5-I17)/C17)*0.02 -> 48.251887 | Q17: =(($V$5-J17)/D17)*0.02 -> 47.775129 | R17: =(P17+Q17)/2 -> 48.013508 | S17: =STDEV(P17:Q17) -> 0.33711885
B18: 400 | C18: 0.1 | D18: 0.1 | E18: 0.226 | F18: 0.138 | G18: =E18*50 -> 11.3 | H18: =F18*50 -> 6.9 | I18: =(G18-0.0244)/0.1678 -> 67.196663 | J18: =(H18-0.0244)/0.1678 -> 40.97497 | K18: =(I18+J18)/2 -> 54.085816 | L18: =(($V$6-I18)/$V$6)*100 -> 81.553392 | M18: =(($V$6-J18)/$V$6)*100 -> 88.751685 | N18: =(L18+M18)/2 -> 85.152538 | O18: =STDEV(L18:M18) -> 5.089962 | P18: =(($V$6-I18)/C18)*0.02 -> 59.415971 | Q18: =(($V$6-J18)/D18)*0.02 -> 64.66031 | R18: =(P18+Q18)/2 -> 62.038141 | S18: =STDEV(P18:Q18) -> 3.7083073
B21: 15 ºC
B22: Fibra da Palma tratada com Ácido (H3PO4)
B24: Concentrações | C24: massa de semente (g) | E24: Absorbâncias (nm) | G24: Fator diluição | I24: Ce (ppm) | K24: Média (ppm) | L24: % Remoção | N24: Média % | O24: Desv P | P24: QE (mg/g) | R24: Média | S24: Desv P
B25: 100 | C25: 0.1 | D25: 0.1 | E25: 0.013 | F25: 0.011 | G25: =E25*50 -> 0.65 | H25: =F25*50 -> 0.55 | I25: =(G25-0.0244)/0.1678 -> 3.7282479 | J25: =(H25-0.0244)/0.1678 -> 3.1323004 | K25: =(I25+J25)/2 -> 3.4302741 | L25: =(($V$3-I25)/$V$3)*100 -> 95.882115 | M25: =(($V$3-J25)/$V$3)*100 -> 96.540345 | N25: =(L25+M25)/2 -> 96.21123 | O25: =STDEV(L25:M25) -> 0.46543863 | P25: =(($V$3-I25)/C25)*0.02 -> 17.361939 | Q25: =(($V$3-J25)/D25)*0.02 -> 17.481128 | R25: =(P25+Q25)/2 -> 17.421534 | S25: =STDEV(P25:Q25) -> 0.084279712
B26: 200 | C26: 0.1 | D26: 0.1 | E26: 0.247 | F26: 0.276 | G26: =E26*50 -> 12.35 | H26: =F26*50 -> 13.8 | I26: =(G26-0.0244)/0.1678 -> 73.454112 | J26: =(H26-0.0244)/0.1678 -> 82.095352 | K26: =(I26+J26)/2 -> 77.774732 | L26: =(($V$4-I26)/$V$4)*100 -> 62.940483 | M26: =(($V$4-J26)/$V$4)*100 -> 58.580752 | N26: =(L26+M26)/2 -> 60.760618 | O26: =STDEV(L26:M26) -> 3.0827953 | P26: =(($V$4-I26)/C26)*0.02 -> 24.950338 | Q26: =(($V$4-J26)/D26)*0.02 -> 23.22209 | R26: =(P26+Q26)/2 -> 24.086214 | S26: =STDEV(P26:Q26) -> 1.2220558
B27: 300 | C27: 0.1 | D27: 0.1 | E27: 0.444 | F27: 0.418 | G27: =E27*50 -> 22.2 | H27: =F27*50 -> 20.9 | I27: =(G27-0.0244)/0.1678 -> 132.15495 | J27: =(H27-0.0244)/0.1678 -> 124.40763 | K27: =(I27+J27)/2 -> 128.28129 | L27: =(($V$5-I27)/$V$5)*100 -> 51.485195 | M27: =(($V$5-J27)/$V$5)*100 -> 54.329278 | N27: =(L27+M27)/2 -> 52.907236 | O27: =STDEV(L27:M27) -> 2.0110704 | P27: =(($V$5-I27)/C27)*0.02 -> 28.049265 | Q27: =(($V$5-J27)/D27)*0.02 -> 29.598729 | R27: =(P27+Q27)/2 -> 28.823997 | S27: =STDEV(P27:Q27) -> 1.0956363
B28: 400 | C28: 0.1 | D28: 0.1 | E28: 0.754 | F28: 0.733 | G28: =E28*50 -> 37.7 | H28: =F28*50 -> 36.65 | I28: 200 | J28: 200 | K28: =(I28+J28)/2 -> 200 | L28: =(($V$6-I28)/$V$6)*100 -> 45.096653 | M28: =(($V$6-J28)/$V$6)*100 -> 45.096653 | N28: =(L28+M28)/2 -> 45.096653 | O28: =STDEV(L28:M28) -> 0 | P28: =(($V$6-I28)/C28)*0.02 -> 32.855304 | Q28: =(($V$6-J28)/D28)*0.02 -> 32.855304 | R28: =(P28+Q28)/2 -> 32.855304 | S28: =STDEV(P28:Q28) -> 0
B32: 15 ºC
B33: Fibra da Palma In Natura
B35: Concentrações | C35: massa de semente (g) | E35: Absorbâncias (nm) | G35: Fator diluição | I35: Ce (ppm) | K35: Média (ppm) | L35: % Remoção | N35: Média % | O35: Desv P | P35: QE (mg/g) | R35: Média | S35: Desv P
B36: 100 | C36: 0.1 | D36: 0.1 | E36: 0.051 | F36: 0.047 | G36: =E36*50 -> 2.55 | H36: =F36*50 -> 2.35 | I36: =(G36-0.0244)/0.1678 -> 15.051251 | J36: =(H36-0.0244)/0.1678 -> 13.859356 | K36: =(I36+J36)/2 -> 14.455304 | L36: =(($V$3-I36)/$V$3)*100 -> 83.375753 | M36: =(($V$3-J36)/$V$3)*100 -> 84.692212 | N36: =(L36+M36)/2 -> 84.033982 | O36: =STDEV(L36:M36) -> 0.93087726 | P36: =(($V$3-I36)/C36)*0.02 -> 15.097338 | Q36: =(($V$3-J36)/D36)*0.02 -> 15.335717 | R36: =(P36+Q36)/2 -> 15.216528 | S36: =STDEV(P36:Q36) -> 0.16855942
B37: 200 | C37: 0.1 | D37: 0.1 | E37: 0.255 | F37: 0.264 | G37: =E37*50 -> 12.75 | H37: =F37*50 -> 13.2 | I37: =(G37-0.0244)/0.1678 -> 75.837902 | J37: =(H37-0.0244)/0.1678 -> 78.519666 | K37: =(I37+J37)/2 -> 77.178784 | L37: =(($V$4-I37)/$V$4)*100 -> 61.737799 | M37: =(($V$4-J37)/$V$4)*100 -> 60.384779 | N37: =(L37+M37)/2 -> 61.061289 | O37: =STDEV(L37:M37) -> 0.95672957 | P37: =(($V$4-I37)/C37)*0.02 -> 24.47358 | Q37: =(($V$4-J37)/D37)*0.02 -> 23.937227 | R37: =(P37+Q37)/2 -> 24.205403 | S37: =STDEV(P37:Q37) -> 0.3792587
B38: 300 | C38: 0.1 | D38: 0.1 | E38: 0.505 | F38: 0.504 | G38: =E38*50 -> 25.25 | H38: =F38*50 -> 25.2 | I38: =(G38-0.0244)/0.1678 -> 150.33135 | J38: =(H38-0.0244)/0.1678 -> 150.03337 | K38: =(I38+J38)/2 -> 150.18236 | L38: =(($V$5-I38)/$V$5)*100 -> 44.812538 | M38: =(($V$5-J38)/$V$5)*100 -> 44.921926 | N38: =(L38+M38)/2 -> 44.867232 | O38: =STDEV(L38:M38) -> 0.07734886 | P38: =(($V$5-I38)/C38)*0.02 -> 24.413985 | Q38: =(($V$5-J38)/D38)*0.02 -> 24.47358 | R38: =(P38+Q38)/2 -> 24.443782 | S38: =STDEV(P38:Q38) -> 0.042139856
B39: 400 | C39: 0.1 | D39: 0.1 | E39: 0.794 | F39: 0.819 | G39: =E39*50 -> 39.7 | H39: =F39*50 -> 40.95 | I39: =(G39-0.0244)/0.1678 -> 236.44577 | J39: =(H39-0.0244)/0.1678 -> 243.89511 | K39: =(I39+J39)/2 -> 240.17044 | L39: =(($V$6-I39)/$V$6)*100 -> 35.09168 | M39: =(($V$6-J39)/$V$6)*100 -> 33.04671 | N39: =(L39+M39)/2 -> 34.069195 | O39: =STDEV(L39:M39) -> 1.4460119 | P39: =(($V$6-I39)/C39)*0.02 -> 25.56615 | Q39: =(($V$6-J39)/D39)*0.02 -> 24.076281 | R39: =(P39+Q39)/2 -> 24.821216 | S39: =STDEV(P39:Q39) -> 1.0534964
B41: 30 ºC
B42: Fibra da Palma In Natura
B44: Concentrações | C44: massa de semente (g) | E44: Absorbâncias (nm) | G44: Fator diluição | I44: Ce (ppm) | K44: Média (ppm) | L44: % Remoção | N44: Média % | O44: Desv P | P44: QE (mg/g) | R44: Média | S44: Desv P
B45: 100 | C45: 0.1 | D45: 0.1 | E45: 0.008 | F45: 0.005 | G45: =E45*50 -> 0.4 | H45: =F45*50 -> 0.25 | I45: =(G45-0.0244)/0.1678 -> 2.238379 | J45: =(H45-0.0244)/0.1678 -> 1.3444577 | K45: 5.7914184 | L45: =(($V$3-I45)/$V$3)*100 -> 97.52769 | M45: =(($V$3-J45)/$V$3)*100 -> 98.515034 | N45: =(L45+M45)/2 -> 98.021362 | O45: =STDEV(L45:M45) -> 0.69815795 | P45: =(($V$3-K45)/C45)*0.02 -> 16.949305 | Q45: =(($V$3-J45)/D45)*0.02 -> 17.838697 | R45: =(P45+Q45)/2 -> 17.394001 | S45: =STDEV(P45:Q45) -> 0.62889521
B46: 200 | C46: 0.1 | D46: 0.1 | E46: 0.083 | F46: 0.046 | G46: =E46*50 -> 4.15 | H46: =F46*50 -> 2.3 | I46: =(G46-0.0244)/0.1678 -> 24.586412 | J46: =(H46-0.0244)/0.1678 -> 13.561383 | K46: 19.073897 | L46: =(($V$4-I46)/$V$4)*100 -> 87.595513 | M46: =(($V$4-J46)/$V$4)*100 -> 93.157928 | N46: =(L46+M46)/2 -> 90.376721 | O46: =STDEV(L46:M46) -> 3.9332216 | P46: =(($V$4-K46)/C46)*0.02 -> 35.826381 | Q46: =(($V$4-J46)/D46)*0.02 -> 36.928884 | R46: =(P46+Q46)/2 -> 36.377632 | S46: =STDEV(P46:Q46) -> 0.77958733
B47: 300 | C47: 0.1 | D47: 0.1 | E47: 0.345 | F47: 0.422 | G47: =E47*50 -> 17.25 | H47: =F47*50 -> 21.1 | I47: =(G47-0.0244)/0.1678 -> 102.65554 | J47: =(H47-0.0244)/0.1678 -> 125.59952 | K47: 111.12753 | L47: =(($V$5-I47)/$V$5)*100 -> 62.314588 | M47: =(($V$5-J47)/$V$5)*100 -> 53.891726 | N47: =(L47+M47)/2 -> 58.103157 | O47: =STDEV(L47:M47) -> 5.9558623 | P47: =(($V$5-K47)/C47)*0.02 -> 32.254748 | Q47: =(($V$5-J47)/D47)*0.02 -> 29.36035 | R47: =(P47+Q47)/2 -> 30.807549 | S47: =STDEV(P47:Q47) -> 2.0466485
B48: 400 | C48: 0.1 | D48: 0.1 | E48: 0.882 | F48: 0.718 | G48: =E48*50 -> 44.1 | H48: =F48*50 -> 35.9 | I48: =(G48-0.0244)/0.1678 -> 262.66746 | J48: =(H48-0.0244)/0.1678 -> 213.79976 | K48: 150 | L48: =(($V$6-I48)/$V$6)*100 -> 27.893387 | M48: =(($V$6-J48)/$V$6)*100 -> 41.308388 | N48: =(L48+M48)/2 -> 34.600887 | O48: =STDEV(L48:M48) -> 9.4858383 | P48: =(($V$6-K48)/C48)*0.02 -> 42.855304 | Q48: =(($V$6-J48)/D48)*0.02 -> 30.095352 | R48: =(P48+Q48)/2 -> 36.475328 | S48: =STDEV(P48:Q48) -> 9.0226488
B50: 30 ºC
B51: Fibra da Palma Base
B52: Concentrações | C52: massa de semente (g) | E52: Absorbâncias (nm) | G52: Fator diluição | I52: Ce (ppm) | K52: Média (ppm) | L52: % Remoção | N52: Média % | O52: Desv P | P52: QE (mg/g) | R52: Média | S52: Desv P
B53: 100 | C53: 0.1 | D53: 0.1 | E53: 0.004 | F53: 0.002 | G53: =E53*50 -> 0.2 | H53: =F53*50 -> 0.1 | I53: =(G53-0.0244)/0.1678 -> 1.0464839 | J53: 1.05 | K53: =(I53+J53)/2 -> 1.048242 | L53: =(($V$3-I53)/$V$3)*100 -> 98.844149 | M53: =(($V$3-J53)/$V$3)*100 -> 98.840265 | N53: =(L53+M53)/2 -> 98.842207 | O53: =STDEV(L53:M53) -> 0.0027460879 | P53: =(($V$3-K53)/C53)*0.02 -> 17.89794 | Q53: =(($V$3-J53)/D53)*0.02 -> 17.897588 | R53: =(P53+Q53)/2 -> 17.897764 | S53: =STDEV(P53:Q53) -> 0.00024862515
B54: 200 | C54: 0.1 | D54: 0.1 | E54: 0.018 | F54: 0.022 | G54: =E54*50 -> 0.9 | H54: =F54*50 -> 1.1 | I54: =(G54-0.0244)/0.1678 -> 5.2181168 | J54: =(H54-0.0244)/0.1678 -> 6.4100119 | K54: =(I54+J54)/2 -> 5.8140644 | L54: =(($V$4-I54)/$V$4)*100 -> 97.367324 | M54: =(($V$4-J54)/$V$4)*100 -> 96.765982 | N54: =(L54+M54)/2 -> 97.066653 | O54: =STDEV(L54:M54) -> 0.42521314 | P54: =(($V$4-I54)/C54)*0.02 -> 38.597537 | Q54: =(($V$4-J54)/D54)*0.02 -> 38.359158 | R54: =(P54+Q54)/2 -> 38.478347 | S54: =STDEV(P54:Q54) -> 0.16855942
B55: 300 | C55: 0.1 | D55: 0.1 | E55: 0.087 | F55: 0.093 | G55: =E55*50 -> 4.35 | H55: =F55*50 -> 4.65 | I55: =(G55-0.0244)/0.1678 -> 25.778308 | J55: =(H55-0.0244)/0.1678 -> 27.56615 | K55: =(I55+J55)/2 -> 26.672229 | L55: =(($V$5-I55)/$V$5)*100 -> 90.536642 | M55: =(($V$5-J55)/$V$5)*100 -> 89.880315 | N55: =(L55+M55)/2 -> 90.208479 | O55: =STDEV(L55:M55) -> 0.46409316 | P55: =(($V$5-I55)/C55)*0.02 -> 49.324593 | Q55: =(($V$5-J55)/D55)*0.02 -> 48.967024 | R55: =(P55+Q55)/2 -> 49.145809 | S55: =STDEV(P55:Q55) -> 0.25283914
...

Sheet Isotermas PALMA
B1: Qmax | C1: KL | D1: RL | E1: RL | F1: Qmax | G1: KL | H1: RL | I1: RL | J1: Qmax | K1: KL | L1: RL | M1: RL | Z1: Qmax | AA1: KL | AB1: RL | AC1: RL | AD1: Qmax | AE1: KL | AF1: RL | AG1: RL | AH1: Qmax | AI1: KL | AJ1: RL | AK1: RL | AX1: Qmax | AY1: KL | AZ1: RL | BA1: RL | BB1: Qmax | BC1: KL | BD1: RL | BE1: RL | BF1: Qmax | BG1: KL | BH1: RL | BI1: RL
B2: =1/0.016 -> 62.5 | C2: =1/(B2*0.0613) -> 0.26101142 | D2: =1/(1+(C2*100)) -> 0.036898814 | E2: =1/(1+(C2*400)) -> 0.0094872549 | F2: =1/0.0296 -> 33.783784 | G2: =1/(F2*0.4558) -> 0.064940763 | H2: =1/(1+(G2*100)) -> 0.13343873 | I2: =1/(1+(G2*400)) -> 0.037069568 | J2: =1/0.0389 -> 25.706941 | K2: =1/(J2*0.3036) -> 0.12812912 | L2: =1/(1+(K2*100)) -> 0.072396032 | M2: =1/(1+(K2*400)) -> 0.019138153 | Z2: =1/0.0148 -> 67.567568 | AA2: =1/(Z2*0.0588) -> 0.25170068 | AB2: =1/(1+($AA$2*Y6)) -> 0.038211593 | AC2: =1/(1+($AA$2*Y9)) -> 0.0098347494 | AD2: =1/0.0224 -> 44.642857 | AE2: =1/(AD2*0.0643) -> 0.34836703 | AF2: =1/(1+($AE$2*Y6)) -> 0.027904353 | AG2: =1/(1+($AE$2*Y9)) -> 0.0071252064 | AH2: =1/0.0241 -> 41.493776 | AI2: =1/(AH2*0.2001) -> 0.12043978 | AJ2: =1/(1+($AI$2*100)) -> 0.076663729 | AK2: =1/(1+($AI$2*400)) -> 0.020335159 | AX2: =1/0.0166 -> 60.240964 | AY2: =1/(AX2*0.0608) -> 0.27302632 | AZ2: =1/(1+($AY$2*100)) -> 0.035332404 | BA2: =1/(1+($AY$2*400)) -> 0.0090735435 | BB2: =1/0.0332 -> 30.120482 | BC2: =1/(BB2*(0.6813)) -> 0.048730368 | BD2: =1/(1+($BC$2*100)) -> 0.17026966 | BE2: =1/(1+($BC$2*400)) -> 0.048799181 | BF2: =1/0.0369 -> 27.100271 | BG2: =1/(BF2*0.2668) -> 0.13830585 | BH2: =1/(1+($BG$2*100)) -> 0.067428225 | BI2: =1/(1+($BG$2*400)) -> 0.017754945
B3: Langmuir (15±2 ℃) | Z3: Langmuir (30±3 ℃) | AX3: Langmuir (45±3 ℃)
B4: Base | F4: Ácido | J4: In natura | Z4: Base | AD4: Ácido | AH4: In natura | AX4: Base | BB4: Ácido | BF4: In natura
A5: Ci | B5: Ce médio | C5: Qe médio | D5: Ce/Qe | E5: Qe Cal | F5: Ce médio | G5: Qe médio | H5: Ce/Qe | I5: Qe Cal | J5: Ce médio | K5: Qe médio | L5: Ce/Qe | M5: Qe Cal | Y5: Ci | Z5: Ce médio | AA5: Qe médio | AB5: Ce/Qe | AC5: Qe Cal | AD5: Ce médio | AE5: Qe médio | AF5: Ce/Qe | AG5: Qe Cal | AH5: Ce médio | AI5: Qe médio | AJ5: Ce/Qe | AK5: Qe Cal | AW5: Ci | AX5: Ce médio | AY5: Qe médio | AZ5: Ce/Qe | BA5: Qe Cal | BB5: Ce médio | BC5: Qe médio | BD5: Ce/Qe | BE5: Qe Cal | BF5: Ce médio | BG5: Qe médio | BH5: Ce/Qe | BI5: Qe Cal
A6: 100 | B6: 1.01 | C6: 17.91 | D6: =B6/C6 -> 0.056393076 | E6: =$B$2*$C$2*B6/(1+$C$2*B6) -> 13.038988 | F6: 3.4302741 | G6: 17.421534 | H6: =F6/G6 -> 0.19689852 | I6: =$F$2*$G$2*F6/(1+$G$2*F6) -> 6.1547674 | J6: 14.455304 | K6: 15.216528 | L6: =J6/K6 -> 0.94997389 | M6: =$J$2*$K$2*J6/(1+$K$2*J6) -> 16.693746 | Y6: 100 | Z6: 1.05 | AA6: 17.9 | AB6: =Z6/AA6 -> 0.058659218 | AC6: =$Z$2*$AA$2*Z6/(1+$AA$2*Z6) -> 14.124294 | AD6: 1.03 | AE6: 17.9 | AF6: =AD6/AE6 -> 0.057541899 | AG6: =$AD$2*$AE$2*AD6/(1+$AE$2*AD6) -> 11.788674 | AH6: 5.7914184 | AI6: 16.949305 | AJ6: =AH6/AI6 -> 0.34169061 | AK6: =$AH$2*$AI$2*AH6/(1+$AI$2*AH6) -> 17.049972 | AW6: 100 | AX6: 1.7914184 | AY6: 17.749305 | AZ6: =AX6/AY6 -> 0.10092893 | BA6: =$AX$2*$AY$2*AX6/(1+$AY$2*AX6) -> 19.786469 | BB6: 14.902265 | BC6: 15.127135 | BD6: =BB6/BC6 -> 0.9851346 | BE6: =$BB$2*$BC$2*BB6/(1+$BC$2*BB6) -> 12.671399 | BF6: 3.4302741 | BG6: 17.421534 | BH6: =BF6/BG6 -> 0.19689852 | BI6: =$BF$2*$BG$2*BF6/(1+$BG$2*BF6) -> 8.7200653
A7: 200 | B7: 4.3241955 | C7: 38.776321 | D7: =B7/C7 -> 0.11151639 | E7: =$B$2*$C$2*B7/(1+$C$2*B7) -> 33.138866 | F7: 77.774732 | G7: 24.086214 | H7: =F7/G7 -> 3.2290144 | I7: =$F$2*$G$2*F7/(1+$G$2*F7) -> 28.20038 | J7: 77.178784 | K7: 24.205403 | L7: =J7/K7 -> 3.1884941 | M7: =$J$2*$K$2*J7/(1+$K$2*J7) -> 23.346091 | Y7: 200 | Z7: 5.8140644 | AA7: 38.478347 | AB7: =Z7/AA7 -> 0.15109964 | AC7: =$Z$2*$AA$2*Z7/(1+$AA$2*Z7) -> 40.13903 | AD7: 16.392133 | AE7: 36.362733 | AF7: =AD7/AE7 -> 0.45079486 | AG7: =$AD$2*$AE$2*AD7/(1+$AE$2*AD7) -> 37.990149 | AH7: 19.073897 | AI7: 32.254748 | AJ7: =AH7/AI7 -> 0.59135163 | AK7: =$AH$2*$AI$2*AH7/(1+$AI$2*AH7) -> 28.90944 | AW7: 200 | AX7: 4.3241955 | AY7: 38.776321 | AZ7: =AX7/AY7 -> 0.11151639 | BA7: =$AX$2*$AY$2*AX7/(1+$AY$2*AX7) -> 32.61534 | BB7: 97.143027 | BC7: 23 | BD7: =BB7/BC7 -> 4.2236099 | BE7: =$BB$2*$BC$2*BB7/(1+$BC$2*BB7) -> 24.867351 | BF7: 78.81764 | BG7: 23.877632 | BH7: =BF7/BG7 -> 3.3008985 | BI7: =$BF$2*$BG$2*BF7/(1+$BG$2*BF7) -> 24.823117
A8: 300 | B8: 32.333731 | C8: 48.013508 | D8: =B8/C8 -> 0.67342987 | E8: =$B$2*$C$2*B8/(1+$C$2*B8) -> 55.878868 | F8: 128.28129 | G8: 28.823997 | H8: =F8/G8 -> 4.4505031 | I8: =$F$2*$G$2*F8/(1+$G$2*F8) -> 30.163065 | J8: 150.18236 | K8: 24.443782 | L8: =J8/K8 -> 6.1439902 | M8: =$J$2*$K$2*J8/(1+$K$2*J8) -> 24.437007 | Y8: 300 | Z8: 26.672229 | AA8: 52 | AB8: =Z8/AA8 -> 0.51292748 | AC8: =$Z$2*$AA$2*Z8/(1+$AA$2*Z8) -> 58.807824 | AD8: 61.684148 | AE8: 42.143425 | AF8: =AD8/AE8 -> 1.4636719 | AG8: =$AD$2*$AE$2*AD8/(1+$AE$2*AD8) -> 42.657735 | AH8: 111.12753 | AI8: 35.83 | AJ8: =AH8/AI8 -> 3.101522 | AK8: =$AH$2*$AI$2*AH8/(1+$AI$2*AH8) -> 38.609094 | AW8: 300 | AX8: 22.351609 | AY8: 50.009932 | AZ8: =AX8/AY8 -> 0.4469434 | BA8: =$AX$2*$AY$2*AX8/(1+$AY$2*AX8) -> 51.7594 | BB8: 141 | BC8: 26.280254 | BD8: =BB8/BC8 -> 5.3652449 | BE8: =$BB$2*$BC$2*BB8/(1+$BC$2*BB8) -> 26.293706 | BF8: 148.99046 | BG8: 24.682161 | BH8: =BF8/BG8 -> 6.0363622 | BI8: =$BF$2*$BG$2*BF8/(1+$BG$2*BF8) -> 25.845992
